{
 "metadata": {
  "kernelspec": {
   "display_name": "Python 3 (ipykernel)",
   "language": "python",
   "name": "python3"
  },
  "language_info": {
   "codemirror_mode": {
    "name": "ipython",
    "version": 3
   },
   "file_extension": ".py",
   "mimetype": "text/x-python",
   "name": "python",
   "nbconvert_exporter": "python",
   "pygments_lexer": "ipython3",
   "version": "3.12.8"
  }
 },
 "nbformat_minor": 5,
 "nbformat": 4,
 "cells": [
  {
   "id": "be2d61b0-0d47-4349-b4b0-1b767c961644",
   "cell_type": "markdown",
   "source": "# Quantum Espresso Energy Volume Curve Workflow with pyiron_base",
   "metadata": {}
  },
  {
   "id": "0bad2a57-1bd2-4837-94fe-f8c60e211fae",
   "cell_type": "markdown",
   "source": "## Define workflow with pyiron_base",
   "metadata": {}
  },
  {
   "id": "a2ed2608-9e1b-4a81-81cb-5079573ea2d1",
   "cell_type": "code",
   "source": "import numpy as np\nfrom pyiron_base import Project, job\nfrom python_workflow_definition.pyiron_base import write_workflow_json",
   "metadata": {
    "trusted": true
   },
   "outputs": [],
   "execution_count": 1
  },
  {
   "id": "b75c2530-9b89-4185-838f-a17e517fa68f",
   "cell_type": "code",
   "source": "from quantum_espresso_workflow import (\n    calculate_qe as _calculate_qe, \n    generate_structures as _generate_structures, \n    get_bulk_structure as _get_bulk_structure, \n    plot_energy_volume_curve as _plot_energy_volume_curve,\n)",
   "metadata": {
    "trusted": true
   },
   "outputs": [],
   "execution_count": 2
  },
  {
   "id": "07a950ca",
   "cell_type": "code",
   "source": "workflow_json_filename = \"pyiron_base_qe.json\"",
   "metadata": {
    "trusted": true
   },
   "outputs": [],
   "execution_count": 3
  },
  {
   "id": "208ddfb8-dfda-4227-aa1f-3dc29e34ea82",
   "cell_type": "code",
   "source": "calculate_qe = job(_calculate_qe, output_key_lst=[\"energy\", \"volume\", \"structure\"])\ngenerate_structures = job(_generate_structures)\nplot_energy_volume_curve = job(_plot_energy_volume_curve)\nget_bulk_structure = job(_get_bulk_structure)",
   "metadata": {
    "trusted": true
   },
   "outputs": [],
   "execution_count": 4
  },
  {
   "id": "5071d3a0-7c1f-44c5-85e0-dede1566c10c",
   "cell_type": "code",
   "source": "pseudopotentials = {\"Al\": \"Al.pbe-n-kjpaw_psl.1.0.0.UPF\"}",
   "metadata": {
    "trusted": true
   },
   "outputs": [],
   "execution_count": 5
  },
  {
   "id": "13debfcd-362d-4fd0-a91f-5ab33632fceb",
   "cell_type": "code",
   "source": "pr = Project(\"test\")\npr.remove_jobs(recursive=True, silently=True)",
   "metadata": {
    "trusted": true
   },
   "outputs": [
    {
     "data": {
      "application/vnd.jupyter.widget-view+json": {
       "model_id": "02502d277bff46be94b6eba7a2d64f98",
       "version_major": 2,
       "version_minor": 0
      },
      "text/plain": "0it [00:00, ?it/s]"
     },
     "metadata": {},
     "output_type": "display_data"
    }
   ],
   "execution_count": 6
  },
  {
   "id": "1f1cb12f-4001-478d-8ea0-b369f4f2981a",
   "cell_type": "code",
   "source": "structure = get_bulk_structure(\n    element=\"Al\",\n    a=4.05,\n    cubic=True,\n    pyiron_project=pr,\n)",
   "metadata": {
    "trusted": true
   },
   "outputs": [],
   "execution_count": 7
  },
  {
   "id": "4140f07b-af54-41ef-be22-df6b5b53bf95",
   "cell_type": "code",
   "source": "calc_mini = calculate_qe(\n    working_directory=\"mini\",\n    input_dict={\n        \"structure\": structure,\n        \"pseudopotentials\": pseudopotentials,\n        \"kpts\": (3, 3, 3),\n        \"calculation\": \"vc-relax\",\n        \"smearing\": 0.02,\n    },\n    pyiron_project=pr,\n)",
   "metadata": {
    "trusted": true
   },
   "outputs": [],
   "execution_count": 8
  },
  {
   "id": "3c4dae11-8750-42d5-807c-cd19f2b65706",
   "cell_type": "code",
   "source": "number_of_strains = 5\nstructure_lst = generate_structures(  # the generate_structures() function is not available in the workflow graph\n    structure=calc_mini.output.structure,\n    strain_lst=np.linspace(0.9, 1.1, number_of_strains),\n    pyiron_project=pr,\n    list_length=number_of_strains,\n)",
   "metadata": {
    "trusted": true
   },
   "outputs": [],
   "execution_count": 9
  },
  {
   "id": "fdf3b62d-6cce-4312-8a5b-057224e36aca",
   "cell_type": "code",
   "source": "job_strain_lst = []\nfor i, structure_strain in enumerate(structure_lst):\n    calc_strain = calculate_qe(\n        working_directory=\"strain_\" + str(i),\n        input_dict={\n            \"structure\": structure_strain,\n            \"pseudopotentials\": pseudopotentials,\n            \"kpts\": (3, 3, 3),\n            \"calculation\": \"scf\",\n            \"smearing\": 0.02,\n        },\n        pyiron_project=pr,\n    )\n    job_strain_lst.append(calc_strain)",
   "metadata": {
    "trusted": true
   },
   "outputs": [],
   "execution_count": 10
  },
  {
   "id": "b2823306-0a8a-4ae6-bb1f-104e90e2fe41",
   "cell_type": "code",
   "source": "plot = plot_energy_volume_curve(\n    volume_lst=[job.output.volume for job in job_strain_lst],\n    energy_lst=[job.output.energy for job in job_strain_lst],\n    pyiron_project=pr,\n)",
   "metadata": {
    "trusted": true
   },
   "outputs": [],
   "execution_count": 11
  },
  {
   "id": "52646121-335f-48e6-bd5e-a1d69d00e8bc",
   "cell_type": "code",
   "source": "write_workflow_json(delayed_object=plot, file_name=workflow_json_filename)",
   "metadata": {
    "trusted": true
   },
   "outputs": [],
   "execution_count": 12
  },
  {
   "id": "72c8e6e6-8e60-4a4f-81f3-968b4b5f36ee",
   "cell_type": "code",
   "source": "!cat {workflow_json_filename}",
   "metadata": {
    "trusted": true
   },
   "outputs": [
    {
     "name": "stdout",
     "output_type": "stream",
     "text": "{\"nodes\": {\"0\": \"quantum_espresso_workflow.plot_energy_volume_curve\", \"1\": \"python_workflow_definition.shared.get_list\", \"2\": \"quantum_espresso_workflow.calculate_qe\", \"3\": \"python_workflow_definition.shared.get_dict\", \"4\": \"quantum_espresso_workflow.generate_structures\", \"5\": \"quantum_espresso_workflow.calculate_qe\", \"6\": \"python_workflow_definition.shared.get_dict\", \"7\": \"quantum_espresso_workflow.get_bulk_structure\", \"8\": \"quantum_espresso_workflow.calculate_qe\", \"9\": \"python_workflow_definition.shared.get_dict\", \"10\": \"quantum_espresso_workflow.calculate_qe\", \"11\": \"python_workflow_definition.shared.get_dict\", \"12\": \"quantum_espresso_workflow.calculate_qe\", \"13\": \"python_workflow_definition.shared.get_dict\", \"14\": \"quantum_espresso_workflow.calculate_qe\", \"15\": \"python_workflow_definition.shared.get_dict\", \"16\": \"python_workflow_definition.shared.get_list\", \"17\": \"strain_0\", \"18\": \"mini\", \"19\": \"Al\", \"20\": 4.05, \"21\": true, \"22\": {\"Al\": \"Al.pbe-n-kjpaw_psl.1.0.0.UPF\"}, \"23\": [3, 3, 3], \"24\": \"vc-relax\", \"25\": 0.02, \"26\": [0.9, 0.9500000000000001, 1.0, 1.05, 1.1], \"27\": \"scf\", \"28\": \"strain_1\", \"29\": \"strain_2\", \"30\": \"strain_3\", \"31\": \"strain_4\"}, \"edges\": [{\"target\": 0, \"targetHandle\": \"volume_lst\", \"source\": 1, \"sourceHandle\": null}, {\"target\": 1, \"targetHandle\": \"0\", \"source\": 2, \"sourceHandle\": \"volume\"}, {\"target\": 2, \"targetHandle\": \"working_directory\", \"source\": 17, \"sourceHandle\": null}, {\"target\": 2, \"targetHandle\": \"input_dict\", \"source\": 3, \"sourceHandle\": null}, {\"target\": 3, \"targetHandle\": \"structure\", \"source\": 4, \"sourceHandle\": \"s_0\"}, {\"target\": 4, \"targetHandle\": \"structure\", \"source\": 5, \"sourceHandle\": \"structure\"}, {\"target\": 5, \"targetHandle\": \"working_directory\", \"source\": 18, \"sourceHandle\": null}, {\"target\": 5, \"targetHandle\": \"input_dict\", \"source\": 6, \"sourceHandle\": null}, {\"target\": 6, \"targetHandle\": \"structure\", \"source\": 7, \"sourceHandle\": null}, {\"target\": 7, \"targetHandle\": \"element\", \"source\": 19, \"sourceHandle\": null}, {\"target\": 7, \"targetHandle\": \"a\", \"source\": 20, \"sourceHandle\": null}, {\"target\": 7, \"targetHandle\": \"cubic\", \"source\": 21, \"sourceHandle\": null}, {\"target\": 6, \"targetHandle\": \"pseudopotentials\", \"source\": 22, \"sourceHandle\": null}, {\"target\": 6, \"targetHandle\": \"kpts\", \"source\": 23, \"sourceHandle\": null}, {\"target\": 6, \"targetHandle\": \"calculation\", \"source\": 24, \"sourceHandle\": null}, {\"target\": 6, \"targetHandle\": \"smearing\", \"source\": 25, \"sourceHandle\": null}, {\"target\": 4, \"targetHandle\": \"strain_lst\", \"source\": 26, \"sourceHandle\": null}, {\"target\": 3, \"targetHandle\": \"pseudopotentials\", \"source\": 22, \"sourceHandle\": null}, {\"target\": 3, \"targetHandle\": \"kpts\", \"source\": 23, \"sourceHandle\": null}, {\"target\": 3, \"targetHandle\": \"calculation\", \"source\": 27, \"sourceHandle\": null}, {\"target\": 3, \"targetHandle\": \"smearing\", \"source\": 25, \"sourceHandle\": null}, {\"target\": 1, \"targetHandle\": \"1\", \"source\": 8, \"sourceHandle\": \"volume\"}, {\"target\": 8, \"targetHandle\": \"working_directory\", \"source\": 28, \"sourceHandle\": null}, {\"target\": 8, \"targetHandle\": \"input_dict\", \"source\": 9, \"sourceHandle\": null}, {\"target\": 9, \"targetHandle\": \"structure\", \"source\": 4, \"sourceHandle\": \"s_1\"}, {\"target\": 9, \"targetHandle\": \"pseudopotentials\", \"source\": 22, \"sourceHandle\": null}, {\"target\": 9, \"targetHandle\": \"kpts\", \"source\": 23, \"sourceHandle\": null}, {\"target\": 9, \"targetHandle\": \"calculation\", \"source\": 27, \"sourceHandle\": null}, {\"target\": 9, \"targetHandle\": \"smearing\", \"source\": 25, \"sourceHandle\": null}, {\"target\": 1, \"targetHandle\": \"2\", \"source\": 10, \"sourceHandle\": \"volume\"}, {\"target\": 10, \"targetHandle\": \"working_directory\", \"source\": 29, \"sourceHandle\": null}, {\"target\": 10, \"targetHandle\": \"input_dict\", \"source\": 11, \"sourceHandle\": null}, {\"target\": 11, \"targetHandle\": \"structure\", \"source\": 4, \"sourceHandle\": \"s_2\"}, {\"target\": 11, \"targetHandle\": \"pseudopotentials\", \"source\": 22, \"sourceHandle\": null}, {\"target\": 11, \"targetHandle\": \"kpts\", \"source\": 23, \"sourceHandle\": null}, {\"target\": 11, \"targetHandle\": \"calculation\", \"source\": 27, \"sourceHandle\": null}, {\"target\": 11, \"targetHandle\": \"smearing\", \"source\": 25, \"sourceHandle\": null}, {\"target\": 1, \"targetHandle\": \"3\", \"source\": 12, \"sourceHandle\": \"volume\"}, {\"target\": 12, \"targetHandle\": \"working_directory\", \"source\": 30, \"sourceHandle\": null}, {\"target\": 12, \"targetHandle\": \"input_dict\", \"source\": 13, \"sourceHandle\": null}, {\"target\": 13, \"targetHandle\": \"structure\", \"source\": 4, \"sourceHandle\": \"s_3\"}, {\"target\": 13, \"targetHandle\": \"pseudopotentials\", \"source\": 22, \"sourceHandle\": null}, {\"target\": 13, \"targetHandle\": \"kpts\", \"source\": 23, \"sourceHandle\": null}, {\"target\": 13, \"targetHandle\": \"calculation\", \"source\": 27, \"sourceHandle\": null}, {\"target\": 13, \"targetHandle\": \"smearing\", \"source\": 25, \"sourceHandle\": null}, {\"target\": 1, \"targetHandle\": \"4\", \"source\": 14, \"sourceHandle\": \"volume\"}, {\"target\": 14, \"targetHandle\": \"working_directory\", \"source\": 31, \"sourceHandle\": null}, {\"target\": 14, \"targetHandle\": \"input_dict\", \"source\": 15, \"sourceHandle\": null}, {\"target\": 15, \"targetHandle\": \"structure\", \"source\": 4, \"sourceHandle\": \"s_4\"}, {\"target\": 15, \"targetHandle\": \"pseudopotentials\", \"source\": 22, \"sourceHandle\": null}, {\"target\": 15, \"targetHandle\": \"kpts\", \"source\": 23, \"sourceHandle\": null}, {\"target\": 15, \"targetHandle\": \"calculation\", \"source\": 27, \"sourceHandle\": null}, {\"target\": 15, \"targetHandle\": \"smearing\", \"source\": 25, \"sourceHandle\": null}, {\"target\": 0, \"targetHandle\": \"energy_lst\", \"source\": 16, \"sourceHandle\": null}, {\"target\": 16, \"targetHandle\": \"0\", \"source\": 2, \"sourceHandle\": \"energy\"}, {\"target\": 16, \"targetHandle\": \"1\", \"source\": 8, \"sourceHandle\": \"energy\"}, {\"target\": 16, \"targetHandle\": \"2\", \"source\": 10, \"sourceHandle\": \"energy\"}, {\"target\": 16, \"targetHandle\": \"3\", \"source\": 12, \"sourceHandle\": \"energy\"}, {\"target\": 16, \"targetHandle\": \"4\", \"source\": 14, \"sourceHandle\": \"energy\"}]}"
    }
   ],
   "execution_count": 13
  },
  {
   "id": "7d75a2f6-6fad-49c8-bd29-37cca1b84441",
   "cell_type": "markdown",
   "source": "## Load Workflow with aiida",
   "metadata": {}
  },
  {
   "id": "28760464-2a2c-40c2-9451-20713da2ba2c",
   "cell_type": "code",
   "source": "from aiida import load_profile\n\nload_profile()",
   "metadata": {
    "trusted": true
   },
   "outputs": [
    {
     "data": {
      "text/plain": "Profile<uuid='0911f03384b24f139c7cf96149242165' name='adis'>"
     },
     "execution_count": 14,
     "metadata": {},
     "output_type": "execute_result"
    }
   ],
   "execution_count": 14
  },
  {
   "id": "9e8043aa-dc65-42ba-9871-0714f7f2573b",
   "cell_type": "code",
   "source": "",
   "metadata": {
    "trusted": true
   },
   "outputs": [],
   "execution_count": null
  },
  {
   "id": "b9c0c6e1-a62c-41e6-a9ce-1c010c797e70",
   "cell_type": "code",
   "source": "",
   "metadata": {
    "trusted": true
   },
   "outputs": [],
   "execution_count": null
  },
  {
   "id": "a442fe46-057c-469b-a5e0-173ed4829dfb",
   "cell_type": "code",
   "source": "from python_workflow_definition.aiida import load_workflow_json",
   "metadata": {
    "trusted": true
   },
   "outputs": [],
   "execution_count": 15
  },
  {
   "id": "32fcd4b2-4f0a-442d-b098-827672823796",
   "cell_type": "code",
   "source": "wg = load_workflow_json(file_name=workflow_json_filename)",
   "metadata": {
    "trusted": true
   },
   "outputs": [],
   "execution_count": 16
  },
  {
   "id": "a80b59bd-fe30-49c6-92ca-35ef2d77a6fb",
   "cell_type": "code",
   "source": "result = wg.run()",
   "metadata": {
    "trusted": true
   },
   "outputs": [
    {
     "name": "stderr",
     "output_type": "stream",
     "text": "03/22/2025 08:34:06 AM <193> aiida.orm.nodes.process.workflow.workchain.WorkChainNode: [REPORT] [16|WorkGraphEngine|continue_workgraph]: Continue workgraph.\n03/22/2025 08:34:07 AM <193> aiida.orm.nodes.process.workflow.workchain.WorkChainNode: [REPORT] [16|WorkGraphEngine|continue_workgraph]: tasks ready to run: pickle_node18,pickle_node19,pickle_node20,pickle_node21,pickle_node22,pickle_node23,pickle_node24,pickle_node25,pickle_node26,pickle_node27,pickle_node28,pickle_node29,pickle_node30,pickle_node31,pickle_node32\n03/22/2025 08:34:07 AM <193> aiida.orm.nodes.process.workflow.workchain.WorkChainNode: [REPORT] [16|WorkGraphEngine|run_tasks]: Run task: pickle_node18, type: PYTHONJOB\n"
    },
    {
     "name": "stdout",
     "output_type": "stream",
     "text": "------------------------------------------------------------\nkwargs:  {'value': 'strain_0'}\n"
    },
    {
     "name": "stderr",
     "output_type": "stream",
     "text": "03/22/2025 08:34:08 AM <193> aiida.orm.nodes.process.workflow.workchain.WorkChainNode: [REPORT] [16|WorkGraphEngine|run_tasks]: Run task: pickle_node19, type: PYTHONJOB\n"
    },
    {
     "name": "stdout",
     "output_type": "stream",
     "text": "------------------------------------------------------------\nkwargs:  {'value': 'mini'}\n"
    },
    {
     "name": "stderr",
     "output_type": "stream",
     "text": "03/22/2025 08:34:09 AM <193> aiida.orm.nodes.process.workflow.workchain.WorkChainNode: [REPORT] [16|WorkGraphEngine|run_tasks]: Run task: pickle_node20, type: PYTHONJOB\n"
    },
    {
     "name": "stdout",
     "output_type": "stream",
     "text": "------------------------------------------------------------\nkwargs:  {'value': 'Al'}\n"
    },
    {
     "name": "stderr",
     "output_type": "stream",
     "text": "03/22/2025 08:34:09 AM <193> aiida.orm.nodes.process.workflow.workchain.WorkChainNode: [REPORT] [16|WorkGraphEngine|run_tasks]: Run task: pickle_node21, type: PYTHONJOB\n"
    },
    {
     "name": "stdout",
     "output_type": "stream",
     "text": "------------------------------------------------------------\nkwargs:  {'value': 4.05}\n"
    },
    {
     "name": "stderr",
     "output_type": "stream",
     "text": "03/22/2025 08:34:10 AM <193> aiida.orm.nodes.process.workflow.workchain.WorkChainNode: [REPORT] [16|WorkGraphEngine|run_tasks]: Run task: pickle_node22, type: PYTHONJOB\n"
    },
    {
     "name": "stdout",
     "output_type": "stream",
     "text": "------------------------------------------------------------\nkwargs:  {'value': True}\n"
    },
    {
     "name": "stderr",
     "output_type": "stream",
     "text": "03/22/2025 08:34:11 AM <193> aiida.orm.nodes.process.workflow.workchain.WorkChainNode: [REPORT] [16|WorkGraphEngine|run_tasks]: Run task: pickle_node23, type: PYTHONJOB\n"
    },
    {
     "name": "stdout",
     "output_type": "stream",
     "text": "------------------------------------------------------------\nkwargs:  {'value': {'Al': 'Al.pbe-n-kjpaw_psl.1.0.0.UPF'}}\n"
    },
    {
     "name": "stderr",
     "output_type": "stream",
     "text": "03/22/2025 08:34:12 AM <193> aiida.orm.nodes.process.workflow.workchain.WorkChainNode: [REPORT] [16|WorkGraphEngine|run_tasks]: Run task: pickle_node24, type: PYTHONJOB\n"
    },
    {
     "name": "stdout",
     "output_type": "stream",
     "text": "------------------------------------------------------------\nkwargs:  {'value': [3, 3, 3]}\n"
    },
    {
     "name": "stderr",
     "output_type": "stream",
     "text": "03/22/2025 08:34:13 AM <193> aiida.orm.nodes.process.workflow.workchain.WorkChainNode: [REPORT] [16|WorkGraphEngine|run_tasks]: Run task: pickle_node25, type: PYTHONJOB\n"
    },
    {
     "name": "stdout",
     "output_type": "stream",
     "text": "------------------------------------------------------------\nkwargs:  {'value': 'vc-relax'}\n"
    },
    {
     "name": "stderr",
     "output_type": "stream",
     "text": "03/22/2025 08:34:14 AM <193> aiida.orm.nodes.process.workflow.workchain.WorkChainNode: [REPORT] [16|WorkGraphEngine|run_tasks]: Run task: pickle_node26, type: PYTHONJOB\n"
    },
    {
     "name": "stdout",
     "output_type": "stream",
     "text": "------------------------------------------------------------\nkwargs:  {'value': 0.02}\n"
    },
    {
     "name": "stderr",
     "output_type": "stream",
     "text": "03/22/2025 08:34:15 AM <193> aiida.orm.nodes.process.workflow.workchain.WorkChainNode: [REPORT] [16|WorkGraphEngine|run_tasks]: Run task: pickle_node27, type: PYTHONJOB\n"
    },
    {
     "name": "stdout",
     "output_type": "stream",
     "text": "------------------------------------------------------------\nkwargs:  {'value': [0.9, 0.95, 1.0, 1.05, 1.1]}\n"
    },
    {
     "name": "stderr",
     "output_type": "stream",
     "text": "03/22/2025 08:34:16 AM <193> aiida.orm.nodes.process.workflow.workchain.WorkChainNode: [REPORT] [16|WorkGraphEngine|run_tasks]: Run task: pickle_node28, type: PYTHONJOB\n"
    },
    {
     "name": "stdout",
     "output_type": "stream",
     "text": "------------------------------------------------------------\nkwargs:  {'value': 'scf'}\n"
    },
    {
     "name": "stderr",
     "output_type": "stream",
     "text": "03/22/2025 08:34:17 AM <193> aiida.orm.nodes.process.workflow.workchain.WorkChainNode: [REPORT] [16|WorkGraphEngine|run_tasks]: Run task: pickle_node29, type: PYTHONJOB\n"
    },
    {
     "name": "stdout",
     "output_type": "stream",
     "text": "------------------------------------------------------------\nkwargs:  {'value': 'strain_1'}\n"
    },
    {
     "name": "stderr",
     "output_type": "stream",
     "text": "03/22/2025 08:34:17 AM <193> aiida.orm.nodes.process.workflow.workchain.WorkChainNode: [REPORT] [16|WorkGraphEngine|run_tasks]: Run task: pickle_node30, type: PYTHONJOB\n"
    },
    {
     "name": "stdout",
     "output_type": "stream",
     "text": "------------------------------------------------------------\nkwargs:  {'value': 'strain_2'}\n"
    },
    {
     "name": "stderr",
     "output_type": "stream",
     "text": "03/22/2025 08:34:18 AM <193> aiida.orm.nodes.process.workflow.workchain.WorkChainNode: [REPORT] [16|WorkGraphEngine|run_tasks]: Run task: pickle_node31, type: PYTHONJOB\n"
    },
    {
     "name": "stdout",
     "output_type": "stream",
     "text": "------------------------------------------------------------\nkwargs:  {'value': 'strain_3'}\n"
    },
    {
     "name": "stderr",
     "output_type": "stream",
     "text": "03/22/2025 08:34:20 AM <193> aiida.orm.nodes.process.workflow.workchain.WorkChainNode: [REPORT] [16|WorkGraphEngine|run_tasks]: Run task: pickle_node32, type: PYTHONJOB\n"
    },
    {
     "name": "stdout",
     "output_type": "stream",
     "text": "------------------------------------------------------------\nkwargs:  {'value': 'strain_4'}\n"
    },
    {
     "name": "stderr",
     "output_type": "stream",
     "text": "03/22/2025 08:34:21 AM <193> aiida.orm.nodes.process.workflow.workchain.WorkChainNode: [REPORT] [16|WorkGraphEngine|on_wait]: Process status: Waiting for child processes: 25, 33, 41, 49, 57, 65, 73, 81, 89, 97, 105, 113, 121, 129, 137\n03/22/2025 08:34:37 AM <193> aiida.scheduler.direct: [WARNING] Unrecognized job_state 'p' for job id Activating\n03/22/2025 08:34:37 AM <193> aiida.engine.transports: [ERROR] Exception whilst using transport:\nTraceback (most recent call last):\n  File \"/srv/conda/envs/notebook/lib/python3.12/site-packages/aiida/engine/transports.py\", line 106, in request_transport\n    yield transport_request.future\n  File \"/srv/conda/envs/notebook/lib/python3.12/site-packages/aiida/engine/processes/calcjobs/manager.py\", line 109, in _get_jobs_from_scheduler\n    scheduler_response = scheduler.get_jobs(**kwargs)\n                         ^^^^^^^^^^^^^^^^^^^^^^^^^^^^\n  File \"/srv/conda/envs/notebook/lib/python3.12/site-packages/aiida/schedulers/plugins/direct.py\", line 269, in get_jobs\n    job_stats = super().get_jobs(jobs=jobs, user=user, as_dict=as_dict)\n                ^^^^^^^^^^^^^^^^^^^^^^^^^^^^^^^^^^^^^^^^^^^^^^^^^^^^^^^\n  File \"/srv/conda/envs/notebook/lib/python3.12/site-packages/aiida/schedulers/scheduler.py\", line 361, in get_jobs\n    joblist = self._parse_joblist_output(retval, stdout, stderr)\n              ^^^^^^^^^^^^^^^^^^^^^^^^^^^^^^^^^^^^^^^^^^^^^^^^^^\n  File \"/srv/conda/envs/notebook/lib/python3.12/site-packages/aiida/schedulers/plugins/direct.py\", line 253, in _parse_joblist_output\n    this_job.wallclock_time_seconds = self._convert_time(job[3])\n                                                         ~~~^^^\nIndexError: list index out of range\n\nTask exception was never retrieved\nfuture: <Task finished name='Task-62' coro=<JobsList._ensure_updating.<locals>.updating() done, defined at /srv/conda/envs/notebook/lib/python3.12/site-packages/aiida/engine/processes/calcjobs/manager.py:179> exception=IndexError('list index out of range')>\nTraceback (most recent call last):\n  File \"/srv/conda/envs/notebook/lib/python3.12/asyncio/tasks.py\", line 314, in __step_run_and_handle_result\n    result = coro.send(None)\n             ^^^^^^^^^^^^^^^\n  File \"/srv/conda/envs/notebook/lib/python3.12/site-packages/aiida/engine/processes/calcjobs/manager.py\", line 181, in updating\n    await self._update_job_info()\n  File \"/srv/conda/envs/notebook/lib/python3.12/site-packages/aiida/engine/processes/calcjobs/manager.py\", line 132, in _update_job_info\n    self._jobs_cache = await self._get_jobs_from_scheduler()\n                       ^^^^^^^^^^^^^^^^^^^^^^^^^^^^^^^^^^^^^\n  File \"/srv/conda/envs/notebook/lib/python3.12/site-packages/aiida/engine/processes/calcjobs/manager.py\", line 109, in _get_jobs_from_scheduler\n    scheduler_response = scheduler.get_jobs(**kwargs)\n                         ^^^^^^^^^^^^^^^^^^^^^^^^^^^^\n  File \"/srv/conda/envs/notebook/lib/python3.12/site-packages/aiida/schedulers/plugins/direct.py\", line 269, in get_jobs\n    job_stats = super().get_jobs(jobs=jobs, user=user, as_dict=as_dict)\n                ^^^^^^^^^^^^^^^^^^^^^^^^^^^^^^^^^^^^^^^^^^^^^^^^^^^^^^^\n  File \"/srv/conda/envs/notebook/lib/python3.12/site-packages/aiida/schedulers/scheduler.py\", line 361, in get_jobs\n    joblist = self._parse_joblist_output(retval, stdout, stderr)\n              ^^^^^^^^^^^^^^^^^^^^^^^^^^^^^^^^^^^^^^^^^^^^^^^^^^\n  File \"/srv/conda/envs/notebook/lib/python3.12/site-packages/aiida/schedulers/plugins/direct.py\", line 253, in _parse_joblist_output\n    this_job.wallclock_time_seconds = self._convert_time(job[3])\n                                                         ~~~^^^\nIndexError: list index out of range\n03/22/2025 08:34:37 AM <193> aiida.orm.nodes.process.calculation.calcjob.CalcJobNode: [ERROR] iteration 1 of do_update excepted, retrying after 20 seconds\nTraceback (most recent call last):\n  File \"/srv/conda/envs/notebook/lib/python3.12/site-packages/aiida/engine/utils.py\", line 205, in exponential_backoff_retry\n    result = await coro()\n             ^^^^^^^^^^^^\n  File \"/srv/conda/envs/notebook/lib/python3.12/site-packages/aiida/engine/processes/calcjobs/tasks.py\", line 195, in do_update\n    job_info = await cancellable.with_interrupt(update_request)\n               ^^^^^^^^^^^^^^^^^^^^^^^^^^^^^^^^^^^^^^^^^^^^^^^^\n  File \"/srv/conda/envs/notebook/lib/python3.12/site-packages/aiida/engine/utils.py\", line 115, in with_interrupt\n    result = await next(wait_iter)\n             ^^^^^^^^^^^^^^^^^^^^^\n  File \"/srv/conda/envs/notebook/lib/python3.12/asyncio/tasks.py\", line 631, in _wait_for_one\n    return f.result()  # May raise f.exception().\n           ^^^^^^^^^^\n  File \"/srv/conda/envs/notebook/lib/python3.12/asyncio/futures.py\", line 202, in result\n    raise self._exception.with_traceback(self._exception_tb)\n  File \"/srv/conda/envs/notebook/lib/python3.12/site-packages/aiida/engine/processes/calcjobs/manager.py\", line 132, in _update_job_info\n    self._jobs_cache = await self._get_jobs_from_scheduler()\n                       ^^^^^^^^^^^^^^^^^^^^^^^^^^^^^^^^^^^^^\n  File \"/srv/conda/envs/notebook/lib/python3.12/site-packages/aiida/engine/processes/calcjobs/manager.py\", line 109, in _get_jobs_from_scheduler\n    scheduler_response = scheduler.get_jobs(**kwargs)\n                         ^^^^^^^^^^^^^^^^^^^^^^^^^^^^\n  File \"/srv/conda/envs/notebook/lib/python3.12/site-packages/aiida/schedulers/plugins/direct.py\", line 269, in get_jobs\n    job_stats = super().get_jobs(jobs=jobs, user=user, as_dict=as_dict)\n                ^^^^^^^^^^^^^^^^^^^^^^^^^^^^^^^^^^^^^^^^^^^^^^^^^^^^^^^\n  File \"/srv/conda/envs/notebook/lib/python3.12/site-packages/aiida/schedulers/scheduler.py\", line 361, in get_jobs\n    joblist = self._parse_joblist_output(retval, stdout, stderr)\n              ^^^^^^^^^^^^^^^^^^^^^^^^^^^^^^^^^^^^^^^^^^^^^^^^^^\n  File \"/srv/conda/envs/notebook/lib/python3.12/site-packages/aiida/schedulers/plugins/direct.py\", line 253, in _parse_joblist_output\n    this_job.wallclock_time_seconds = self._convert_time(job[3])\n                                                         ~~~^^^\nIndexError: list index out of range\n03/22/2025 08:34:37 AM <193> aiida.orm.nodes.process.calculation.calcjob.CalcJobNode: [ERROR] iteration 1 of do_update excepted, retrying after 20 seconds\nTraceback (most recent call last):\n  File \"/srv/conda/envs/notebook/lib/python3.12/site-packages/aiida/engine/utils.py\", line 205, in exponential_backoff_retry\n    result = await coro()\n             ^^^^^^^^^^^^\n  File \"/srv/conda/envs/notebook/lib/python3.12/site-packages/aiida/engine/processes/calcjobs/tasks.py\", line 195, in do_update\n    job_info = await cancellable.with_interrupt(update_request)\n               ^^^^^^^^^^^^^^^^^^^^^^^^^^^^^^^^^^^^^^^^^^^^^^^^\n  File \"/srv/conda/envs/notebook/lib/python3.12/site-packages/aiida/engine/utils.py\", line 115, in with_interrupt\n    result = await next(wait_iter)\n             ^^^^^^^^^^^^^^^^^^^^^\n  File \"/srv/conda/envs/notebook/lib/python3.12/asyncio/tasks.py\", line 631, in _wait_for_one\n    return f.result()  # May raise f.exception().\n           ^^^^^^^^^^\n  File \"/srv/conda/envs/notebook/lib/python3.12/asyncio/futures.py\", line 202, in result\n    raise self._exception.with_traceback(self._exception_tb)\n  File \"/srv/conda/envs/notebook/lib/python3.12/site-packages/aiida/engine/processes/calcjobs/manager.py\", line 132, in _update_job_info\n    self._jobs_cache = await self._get_jobs_from_scheduler()\n                       ^^^^^^^^^^^^^^^^^^^^^^^^^^^^^^^^^^^^^\n  File \"/srv/conda/envs/notebook/lib/python3.12/site-packages/aiida/engine/processes/calcjobs/manager.py\", line 109, in _get_jobs_from_scheduler\n    scheduler_response = scheduler.get_jobs(**kwargs)\n                         ^^^^^^^^^^^^^^^^^^^^^^^^^^^^\n  File \"/srv/conda/envs/notebook/lib/python3.12/site-packages/aiida/schedulers/plugins/direct.py\", line 269, in get_jobs\n    job_stats = super().get_jobs(jobs=jobs, user=user, as_dict=as_dict)\n                ^^^^^^^^^^^^^^^^^^^^^^^^^^^^^^^^^^^^^^^^^^^^^^^^^^^^^^^\n  File \"/srv/conda/envs/notebook/lib/python3.12/site-packages/aiida/schedulers/scheduler.py\", line 361, in get_jobs\n    joblist = self._parse_joblist_output(retval, stdout, stderr)\n              ^^^^^^^^^^^^^^^^^^^^^^^^^^^^^^^^^^^^^^^^^^^^^^^^^^\n  File \"/srv/conda/envs/notebook/lib/python3.12/site-packages/aiida/schedulers/plugins/direct.py\", line 253, in _parse_joblist_output\n    this_job.wallclock_time_seconds = self._convert_time(job[3])\n                                                         ~~~^^^\nIndexError: list index out of range\n03/22/2025 08:34:37 AM <193> aiida.orm.nodes.process.calculation.calcjob.CalcJobNode: [ERROR] iteration 1 of do_update excepted, retrying after 20 seconds\nTraceback (most recent call last):\n  File \"/srv/conda/envs/notebook/lib/python3.12/site-packages/aiida/engine/utils.py\", line 205, in exponential_backoff_retry\n    result = await coro()\n             ^^^^^^^^^^^^\n  File \"/srv/conda/envs/notebook/lib/python3.12/site-packages/aiida/engine/processes/calcjobs/tasks.py\", line 195, in do_update\n    job_info = await cancellable.with_interrupt(update_request)\n               ^^^^^^^^^^^^^^^^^^^^^^^^^^^^^^^^^^^^^^^^^^^^^^^^\n  File \"/srv/conda/envs/notebook/lib/python3.12/site-packages/aiida/engine/utils.py\", line 115, in with_interrupt\n    result = await next(wait_iter)\n             ^^^^^^^^^^^^^^^^^^^^^\n  File \"/srv/conda/envs/notebook/lib/python3.12/asyncio/tasks.py\", line 631, in _wait_for_one\n    return f.result()  # May raise f.exception().\n           ^^^^^^^^^^\n  File \"/srv/conda/envs/notebook/lib/python3.12/asyncio/futures.py\", line 202, in result\n    raise self._exception.with_traceback(self._exception_tb)\n  File \"/srv/conda/envs/notebook/lib/python3.12/site-packages/aiida/engine/processes/calcjobs/manager.py\", line 132, in _update_job_info\n    self._jobs_cache = await self._get_jobs_from_scheduler()\n                       ^^^^^^^^^^^^^^^^^^^^^^^^^^^^^^^^^^^^^\n  File \"/srv/conda/envs/notebook/lib/python3.12/site-packages/aiida/engine/processes/calcjobs/manager.py\", line 109, in _get_jobs_from_scheduler\n    scheduler_response = scheduler.get_jobs(**kwargs)\n                         ^^^^^^^^^^^^^^^^^^^^^^^^^^^^\n  File \"/srv/conda/envs/notebook/lib/python3.12/site-packages/aiida/schedulers/plugins/direct.py\", line 269, in get_jobs\n    job_stats = super().get_jobs(jobs=jobs, user=user, as_dict=as_dict)\n                ^^^^^^^^^^^^^^^^^^^^^^^^^^^^^^^^^^^^^^^^^^^^^^^^^^^^^^^\n  File \"/srv/conda/envs/notebook/lib/python3.12/site-packages/aiida/schedulers/scheduler.py\", line 361, in get_jobs\n    joblist = self._parse_joblist_output(retval, stdout, stderr)\n              ^^^^^^^^^^^^^^^^^^^^^^^^^^^^^^^^^^^^^^^^^^^^^^^^^^\n  File \"/srv/conda/envs/notebook/lib/python3.12/site-packages/aiida/schedulers/plugins/direct.py\", line 253, in _parse_joblist_output\n    this_job.wallclock_time_seconds = self._convert_time(job[3])\n                                                         ~~~^^^\nIndexError: list index out of range\n03/22/2025 08:34:37 AM <193> aiida.orm.nodes.process.calculation.calcjob.CalcJobNode: [ERROR] iteration 1 of do_update excepted, retrying after 20 seconds\nTraceback (most recent call last):\n  File \"/srv/conda/envs/notebook/lib/python3.12/site-packages/aiida/engine/utils.py\", line 205, in exponential_backoff_retry\n    result = await coro()\n             ^^^^^^^^^^^^\n  File \"/srv/conda/envs/notebook/lib/python3.12/site-packages/aiida/engine/processes/calcjobs/tasks.py\", line 195, in do_update\n    job_info = await cancellable.with_interrupt(update_request)\n               ^^^^^^^^^^^^^^^^^^^^^^^^^^^^^^^^^^^^^^^^^^^^^^^^\n  File \"/srv/conda/envs/notebook/lib/python3.12/site-packages/aiida/engine/utils.py\", line 115, in with_interrupt\n    result = await next(wait_iter)\n             ^^^^^^^^^^^^^^^^^^^^^\n  File \"/srv/conda/envs/notebook/lib/python3.12/asyncio/tasks.py\", line 631, in _wait_for_one\n    return f.result()  # May raise f.exception().\n           ^^^^^^^^^^\n  File \"/srv/conda/envs/notebook/lib/python3.12/asyncio/futures.py\", line 202, in result\n    raise self._exception.with_traceback(self._exception_tb)\n  File \"/srv/conda/envs/notebook/lib/python3.12/site-packages/aiida/engine/processes/calcjobs/manager.py\", line 132, in _update_job_info\n    self._jobs_cache = await self._get_jobs_from_scheduler()\n                       ^^^^^^^^^^^^^^^^^^^^^^^^^^^^^^^^^^^^^\n  File \"/srv/conda/envs/notebook/lib/python3.12/site-packages/aiida/engine/processes/calcjobs/manager.py\", line 109, in _get_jobs_from_scheduler\n    scheduler_response = scheduler.get_jobs(**kwargs)\n                         ^^^^^^^^^^^^^^^^^^^^^^^^^^^^\n  File \"/srv/conda/envs/notebook/lib/python3.12/site-packages/aiida/schedulers/plugins/direct.py\", line 269, in get_jobs\n    job_stats = super().get_jobs(jobs=jobs, user=user, as_dict=as_dict)\n                ^^^^^^^^^^^^^^^^^^^^^^^^^^^^^^^^^^^^^^^^^^^^^^^^^^^^^^^\n  File \"/srv/conda/envs/notebook/lib/python3.12/site-packages/aiida/schedulers/scheduler.py\", line 361, in get_jobs\n    joblist = self._parse_joblist_output(retval, stdout, stderr)\n              ^^^^^^^^^^^^^^^^^^^^^^^^^^^^^^^^^^^^^^^^^^^^^^^^^^\n  File \"/srv/conda/envs/notebook/lib/python3.12/site-packages/aiida/schedulers/plugins/direct.py\", line 253, in _parse_joblist_output\n    this_job.wallclock_time_seconds = self._convert_time(job[3])\n                                                         ~~~^^^\nIndexError: list index out of range\n03/22/2025 08:34:37 AM <193> aiida.orm.nodes.process.calculation.calcjob.CalcJobNode: [ERROR] iteration 1 of do_update excepted, retrying after 20 seconds\nTraceback (most recent call last):\n  File \"/srv/conda/envs/notebook/lib/python3.12/site-packages/aiida/engine/utils.py\", line 205, in exponential_backoff_retry\n    result = await coro()\n             ^^^^^^^^^^^^\n  File \"/srv/conda/envs/notebook/lib/python3.12/site-packages/aiida/engine/processes/calcjobs/tasks.py\", line 195, in do_update\n    job_info = await cancellable.with_interrupt(update_request)\n               ^^^^^^^^^^^^^^^^^^^^^^^^^^^^^^^^^^^^^^^^^^^^^^^^\n  File \"/srv/conda/envs/notebook/lib/python3.12/site-packages/aiida/engine/utils.py\", line 115, in with_interrupt\n    result = await next(wait_iter)\n             ^^^^^^^^^^^^^^^^^^^^^\n  File \"/srv/conda/envs/notebook/lib/python3.12/asyncio/tasks.py\", line 631, in _wait_for_one\n    return f.result()  # May raise f.exception().\n           ^^^^^^^^^^\n  File \"/srv/conda/envs/notebook/lib/python3.12/asyncio/futures.py\", line 202, in result\n    raise self._exception.with_traceback(self._exception_tb)\n  File \"/srv/conda/envs/notebook/lib/python3.12/site-packages/aiida/engine/processes/calcjobs/manager.py\", line 132, in _update_job_info\n    self._jobs_cache = await self._get_jobs_from_scheduler()\n                       ^^^^^^^^^^^^^^^^^^^^^^^^^^^^^^^^^^^^^\n  File \"/srv/conda/envs/notebook/lib/python3.12/site-packages/aiida/engine/processes/calcjobs/manager.py\", line 109, in _get_jobs_from_scheduler\n    scheduler_response = scheduler.get_jobs(**kwargs)\n                         ^^^^^^^^^^^^^^^^^^^^^^^^^^^^\n  File \"/srv/conda/envs/notebook/lib/python3.12/site-packages/aiida/schedulers/plugins/direct.py\", line 269, in get_jobs\n    job_stats = super().get_jobs(jobs=jobs, user=user, as_dict=as_dict)\n                ^^^^^^^^^^^^^^^^^^^^^^^^^^^^^^^^^^^^^^^^^^^^^^^^^^^^^^^\n  File \"/srv/conda/envs/notebook/lib/python3.12/site-packages/aiida/schedulers/scheduler.py\", line 361, in get_jobs\n    joblist = self._parse_joblist_output(retval, stdout, stderr)\n              ^^^^^^^^^^^^^^^^^^^^^^^^^^^^^^^^^^^^^^^^^^^^^^^^^^\n  File \"/srv/conda/envs/notebook/lib/python3.12/site-packages/aiida/schedulers/plugins/direct.py\", line 253, in _parse_joblist_output\n    this_job.wallclock_time_seconds = self._convert_time(job[3])\n                                                         ~~~^^^\nIndexError: list index out of range\n03/22/2025 08:34:37 AM <193> aiida.orm.nodes.process.calculation.calcjob.CalcJobNode: [ERROR] iteration 1 of do_update excepted, retrying after 20 seconds\nTraceback (most recent call last):\n  File \"/srv/conda/envs/notebook/lib/python3.12/site-packages/aiida/engine/utils.py\", line 205, in exponential_backoff_retry\n    result = await coro()\n             ^^^^^^^^^^^^\n  File \"/srv/conda/envs/notebook/lib/python3.12/site-packages/aiida/engine/processes/calcjobs/tasks.py\", line 195, in do_update\n    job_info = await cancellable.with_interrupt(update_request)\n               ^^^^^^^^^^^^^^^^^^^^^^^^^^^^^^^^^^^^^^^^^^^^^^^^\n  File \"/srv/conda/envs/notebook/lib/python3.12/site-packages/aiida/engine/utils.py\", line 115, in with_interrupt\n    result = await next(wait_iter)\n             ^^^^^^^^^^^^^^^^^^^^^\n  File \"/srv/conda/envs/notebook/lib/python3.12/asyncio/tasks.py\", line 631, in _wait_for_one\n    return f.result()  # May raise f.exception().\n           ^^^^^^^^^^\n  File \"/srv/conda/envs/notebook/lib/python3.12/asyncio/futures.py\", line 202, in result\n    raise self._exception.with_traceback(self._exception_tb)\n  File \"/srv/conda/envs/notebook/lib/python3.12/site-packages/aiida/engine/processes/calcjobs/manager.py\", line 132, in _update_job_info\n    self._jobs_cache = await self._get_jobs_from_scheduler()\n                       ^^^^^^^^^^^^^^^^^^^^^^^^^^^^^^^^^^^^^\n  File \"/srv/conda/envs/notebook/lib/python3.12/site-packages/aiida/engine/processes/calcjobs/manager.py\", line 109, in _get_jobs_from_scheduler\n    scheduler_response = scheduler.get_jobs(**kwargs)\n                         ^^^^^^^^^^^^^^^^^^^^^^^^^^^^\n  File \"/srv/conda/envs/notebook/lib/python3.12/site-packages/aiida/schedulers/plugins/direct.py\", line 269, in get_jobs\n    job_stats = super().get_jobs(jobs=jobs, user=user, as_dict=as_dict)\n                ^^^^^^^^^^^^^^^^^^^^^^^^^^^^^^^^^^^^^^^^^^^^^^^^^^^^^^^\n  File \"/srv/conda/envs/notebook/lib/python3.12/site-packages/aiida/schedulers/scheduler.py\", line 361, in get_jobs\n    joblist = self._parse_joblist_output(retval, stdout, stderr)\n              ^^^^^^^^^^^^^^^^^^^^^^^^^^^^^^^^^^^^^^^^^^^^^^^^^^\n  File \"/srv/conda/envs/notebook/lib/python3.12/site-packages/aiida/schedulers/plugins/direct.py\", line 253, in _parse_joblist_output\n    this_job.wallclock_time_seconds = self._convert_time(job[3])\n                                                         ~~~^^^\nIndexError: list index out of range\n03/22/2025 08:34:37 AM <193> aiida.orm.nodes.process.calculation.calcjob.CalcJobNode: [ERROR] iteration 1 of do_update excepted, retrying after 20 seconds\nTraceback (most recent call last):\n  File \"/srv/conda/envs/notebook/lib/python3.12/site-packages/aiida/engine/utils.py\", line 205, in exponential_backoff_retry\n    result = await coro()\n             ^^^^^^^^^^^^\n  File \"/srv/conda/envs/notebook/lib/python3.12/site-packages/aiida/engine/processes/calcjobs/tasks.py\", line 195, in do_update\n    job_info = await cancellable.with_interrupt(update_request)\n               ^^^^^^^^^^^^^^^^^^^^^^^^^^^^^^^^^^^^^^^^^^^^^^^^\n  File \"/srv/conda/envs/notebook/lib/python3.12/site-packages/aiida/engine/utils.py\", line 115, in with_interrupt\n    result = await next(wait_iter)\n             ^^^^^^^^^^^^^^^^^^^^^\n  File \"/srv/conda/envs/notebook/lib/python3.12/asyncio/tasks.py\", line 631, in _wait_for_one\n    return f.result()  # May raise f.exception().\n           ^^^^^^^^^^\n  File \"/srv/conda/envs/notebook/lib/python3.12/asyncio/futures.py\", line 202, in result\n    raise self._exception.with_traceback(self._exception_tb)\n  File \"/srv/conda/envs/notebook/lib/python3.12/site-packages/aiida/engine/processes/calcjobs/manager.py\", line 132, in _update_job_info\n    self._jobs_cache = await self._get_jobs_from_scheduler()\n                       ^^^^^^^^^^^^^^^^^^^^^^^^^^^^^^^^^^^^^\n  File \"/srv/conda/envs/notebook/lib/python3.12/site-packages/aiida/engine/processes/calcjobs/manager.py\", line 109, in _get_jobs_from_scheduler\n    scheduler_response = scheduler.get_jobs(**kwargs)\n                         ^^^^^^^^^^^^^^^^^^^^^^^^^^^^\n  File \"/srv/conda/envs/notebook/lib/python3.12/site-packages/aiida/schedulers/plugins/direct.py\", line 269, in get_jobs\n    job_stats = super().get_jobs(jobs=jobs, user=user, as_dict=as_dict)\n                ^^^^^^^^^^^^^^^^^^^^^^^^^^^^^^^^^^^^^^^^^^^^^^^^^^^^^^^\n  File \"/srv/conda/envs/notebook/lib/python3.12/site-packages/aiida/schedulers/scheduler.py\", line 361, in get_jobs\n    joblist = self._parse_joblist_output(retval, stdout, stderr)\n              ^^^^^^^^^^^^^^^^^^^^^^^^^^^^^^^^^^^^^^^^^^^^^^^^^^\n  File \"/srv/conda/envs/notebook/lib/python3.12/site-packages/aiida/schedulers/plugins/direct.py\", line 253, in _parse_joblist_output\n    this_job.wallclock_time_seconds = self._convert_time(job[3])\n                                                         ~~~^^^\nIndexError: list index out of range\n03/22/2025 08:34:37 AM <193> aiida.orm.nodes.process.calculation.calcjob.CalcJobNode: [ERROR] iteration 1 of do_update excepted, retrying after 20 seconds\nTraceback (most recent call last):\n  File \"/srv/conda/envs/notebook/lib/python3.12/site-packages/aiida/engine/utils.py\", line 205, in exponential_backoff_retry\n    result = await coro()\n             ^^^^^^^^^^^^\n  File \"/srv/conda/envs/notebook/lib/python3.12/site-packages/aiida/engine/processes/calcjobs/tasks.py\", line 195, in do_update\n    job_info = await cancellable.with_interrupt(update_request)\n               ^^^^^^^^^^^^^^^^^^^^^^^^^^^^^^^^^^^^^^^^^^^^^^^^\n  File \"/srv/conda/envs/notebook/lib/python3.12/site-packages/aiida/engine/utils.py\", line 115, in with_interrupt\n    result = await next(wait_iter)\n             ^^^^^^^^^^^^^^^^^^^^^\n  File \"/srv/conda/envs/notebook/lib/python3.12/asyncio/tasks.py\", line 631, in _wait_for_one\n    return f.result()  # May raise f.exception().\n           ^^^^^^^^^^\n  File \"/srv/conda/envs/notebook/lib/python3.12/asyncio/futures.py\", line 202, in result\n    raise self._exception.with_traceback(self._exception_tb)\n  File \"/srv/conda/envs/notebook/lib/python3.12/site-packages/aiida/engine/processes/calcjobs/manager.py\", line 132, in _update_job_info\n    self._jobs_cache = await self._get_jobs_from_scheduler()\n                       ^^^^^^^^^^^^^^^^^^^^^^^^^^^^^^^^^^^^^\n  File \"/srv/conda/envs/notebook/lib/python3.12/site-packages/aiida/engine/processes/calcjobs/manager.py\", line 109, in _get_jobs_from_scheduler\n    scheduler_response = scheduler.get_jobs(**kwargs)\n                         ^^^^^^^^^^^^^^^^^^^^^^^^^^^^\n  File \"/srv/conda/envs/notebook/lib/python3.12/site-packages/aiida/schedulers/plugins/direct.py\", line 269, in get_jobs\n    job_stats = super().get_jobs(jobs=jobs, user=user, as_dict=as_dict)\n                ^^^^^^^^^^^^^^^^^^^^^^^^^^^^^^^^^^^^^^^^^^^^^^^^^^^^^^^\n  File \"/srv/conda/envs/notebook/lib/python3.12/site-packages/aiida/schedulers/scheduler.py\", line 361, in get_jobs\n    joblist = self._parse_joblist_output(retval, stdout, stderr)\n              ^^^^^^^^^^^^^^^^^^^^^^^^^^^^^^^^^^^^^^^^^^^^^^^^^^\n  File \"/srv/conda/envs/notebook/lib/python3.12/site-packages/aiida/schedulers/plugins/direct.py\", line 253, in _parse_joblist_output\n    this_job.wallclock_time_seconds = self._convert_time(job[3])\n                                                         ~~~^^^\nIndexError: list index out of range\n03/22/2025 08:34:37 AM <193> aiida.orm.nodes.process.calculation.calcjob.CalcJobNode: [ERROR] iteration 1 of do_update excepted, retrying after 20 seconds\nTraceback (most recent call last):\n  File \"/srv/conda/envs/notebook/lib/python3.12/site-packages/aiida/engine/utils.py\", line 205, in exponential_backoff_retry\n    result = await coro()\n             ^^^^^^^^^^^^\n  File \"/srv/conda/envs/notebook/lib/python3.12/site-packages/aiida/engine/processes/calcjobs/tasks.py\", line 195, in do_update\n    job_info = await cancellable.with_interrupt(update_request)\n               ^^^^^^^^^^^^^^^^^^^^^^^^^^^^^^^^^^^^^^^^^^^^^^^^\n  File \"/srv/conda/envs/notebook/lib/python3.12/site-packages/aiida/engine/utils.py\", line 115, in with_interrupt\n    result = await next(wait_iter)\n             ^^^^^^^^^^^^^^^^^^^^^\n  File \"/srv/conda/envs/notebook/lib/python3.12/asyncio/tasks.py\", line 631, in _wait_for_one\n    return f.result()  # May raise f.exception().\n           ^^^^^^^^^^\n  File \"/srv/conda/envs/notebook/lib/python3.12/asyncio/futures.py\", line 202, in result\n    raise self._exception.with_traceback(self._exception_tb)\n  File \"/srv/conda/envs/notebook/lib/python3.12/site-packages/aiida/engine/processes/calcjobs/manager.py\", line 132, in _update_job_info\n    self._jobs_cache = await self._get_jobs_from_scheduler()\n                       ^^^^^^^^^^^^^^^^^^^^^^^^^^^^^^^^^^^^^\n  File \"/srv/conda/envs/notebook/lib/python3.12/site-packages/aiida/engine/processes/calcjobs/manager.py\", line 109, in _get_jobs_from_scheduler\n    scheduler_response = scheduler.get_jobs(**kwargs)\n                         ^^^^^^^^^^^^^^^^^^^^^^^^^^^^\n  File \"/srv/conda/envs/notebook/lib/python3.12/site-packages/aiida/schedulers/plugins/direct.py\", line 269, in get_jobs\n    job_stats = super().get_jobs(jobs=jobs, user=user, as_dict=as_dict)\n                ^^^^^^^^^^^^^^^^^^^^^^^^^^^^^^^^^^^^^^^^^^^^^^^^^^^^^^^\n  File \"/srv/conda/envs/notebook/lib/python3.12/site-packages/aiida/schedulers/scheduler.py\", line 361, in get_jobs\n    joblist = self._parse_joblist_output(retval, stdout, stderr)\n              ^^^^^^^^^^^^^^^^^^^^^^^^^^^^^^^^^^^^^^^^^^^^^^^^^^\n  File \"/srv/conda/envs/notebook/lib/python3.12/site-packages/aiida/schedulers/plugins/direct.py\", line 253, in _parse_joblist_output\n    this_job.wallclock_time_seconds = self._convert_time(job[3])\n                                                         ~~~^^^\nIndexError: list index out of range\n03/22/2025 08:34:37 AM <193> aiida.orm.nodes.process.calculation.calcjob.CalcJobNode: [ERROR] iteration 1 of do_update excepted, retrying after 20 seconds\nTraceback (most recent call last):\n  File \"/srv/conda/envs/notebook/lib/python3.12/site-packages/aiida/engine/utils.py\", line 205, in exponential_backoff_retry\n    result = await coro()\n             ^^^^^^^^^^^^\n  File \"/srv/conda/envs/notebook/lib/python3.12/site-packages/aiida/engine/processes/calcjobs/tasks.py\", line 195, in do_update\n    job_info = await cancellable.with_interrupt(update_request)\n               ^^^^^^^^^^^^^^^^^^^^^^^^^^^^^^^^^^^^^^^^^^^^^^^^\n  File \"/srv/conda/envs/notebook/lib/python3.12/site-packages/aiida/engine/utils.py\", line 115, in with_interrupt\n    result = await next(wait_iter)\n             ^^^^^^^^^^^^^^^^^^^^^\n  File \"/srv/conda/envs/notebook/lib/python3.12/asyncio/tasks.py\", line 631, in _wait_for_one\n    return f.result()  # May raise f.exception().\n           ^^^^^^^^^^\n  File \"/srv/conda/envs/notebook/lib/python3.12/asyncio/futures.py\", line 202, in result\n    raise self._exception.with_traceback(self._exception_tb)\n  File \"/srv/conda/envs/notebook/lib/python3.12/site-packages/aiida/engine/processes/calcjobs/manager.py\", line 132, in _update_job_info\n    self._jobs_cache = await self._get_jobs_from_scheduler()\n                       ^^^^^^^^^^^^^^^^^^^^^^^^^^^^^^^^^^^^^\n  File \"/srv/conda/envs/notebook/lib/python3.12/site-packages/aiida/engine/processes/calcjobs/manager.py\", line 109, in _get_jobs_from_scheduler\n    scheduler_response = scheduler.get_jobs(**kwargs)\n                         ^^^^^^^^^^^^^^^^^^^^^^^^^^^^\n  File \"/srv/conda/envs/notebook/lib/python3.12/site-packages/aiida/schedulers/plugins/direct.py\", line 269, in get_jobs\n    job_stats = super().get_jobs(jobs=jobs, user=user, as_dict=as_dict)\n                ^^^^^^^^^^^^^^^^^^^^^^^^^^^^^^^^^^^^^^^^^^^^^^^^^^^^^^^\n  File \"/srv/conda/envs/notebook/lib/python3.12/site-packages/aiida/schedulers/scheduler.py\", line 361, in get_jobs\n    joblist = self._parse_joblist_output(retval, stdout, stderr)\n              ^^^^^^^^^^^^^^^^^^^^^^^^^^^^^^^^^^^^^^^^^^^^^^^^^^\n  File \"/srv/conda/envs/notebook/lib/python3.12/site-packages/aiida/schedulers/plugins/direct.py\", line 253, in _parse_joblist_output\n    this_job.wallclock_time_seconds = self._convert_time(job[3])\n                                                         ~~~^^^\nIndexError: list index out of range\n03/22/2025 08:34:37 AM <193> aiida.orm.nodes.process.calculation.calcjob.CalcJobNode: [ERROR] iteration 1 of do_update excepted, retrying after 20 seconds\nTraceback (most recent call last):\n  File \"/srv/conda/envs/notebook/lib/python3.12/site-packages/aiida/engine/utils.py\", line 205, in exponential_backoff_retry\n    result = await coro()\n             ^^^^^^^^^^^^\n  File \"/srv/conda/envs/notebook/lib/python3.12/site-packages/aiida/engine/processes/calcjobs/tasks.py\", line 195, in do_update\n    job_info = await cancellable.with_interrupt(update_request)\n               ^^^^^^^^^^^^^^^^^^^^^^^^^^^^^^^^^^^^^^^^^^^^^^^^\n  File \"/srv/conda/envs/notebook/lib/python3.12/site-packages/aiida/engine/utils.py\", line 115, in with_interrupt\n    result = await next(wait_iter)\n             ^^^^^^^^^^^^^^^^^^^^^\n  File \"/srv/conda/envs/notebook/lib/python3.12/asyncio/tasks.py\", line 631, in _wait_for_one\n    return f.result()  # May raise f.exception().\n           ^^^^^^^^^^\n  File \"/srv/conda/envs/notebook/lib/python3.12/asyncio/futures.py\", line 202, in result\n    raise self._exception.with_traceback(self._exception_tb)\n  File \"/srv/conda/envs/notebook/lib/python3.12/site-packages/aiida/engine/processes/calcjobs/manager.py\", line 132, in _update_job_info\n    self._jobs_cache = await self._get_jobs_from_scheduler()\n                       ^^^^^^^^^^^^^^^^^^^^^^^^^^^^^^^^^^^^^\n  File \"/srv/conda/envs/notebook/lib/python3.12/site-packages/aiida/engine/processes/calcjobs/manager.py\", line 109, in _get_jobs_from_scheduler\n    scheduler_response = scheduler.get_jobs(**kwargs)\n                         ^^^^^^^^^^^^^^^^^^^^^^^^^^^^\n  File \"/srv/conda/envs/notebook/lib/python3.12/site-packages/aiida/schedulers/plugins/direct.py\", line 269, in get_jobs\n    job_stats = super().get_jobs(jobs=jobs, user=user, as_dict=as_dict)\n                ^^^^^^^^^^^^^^^^^^^^^^^^^^^^^^^^^^^^^^^^^^^^^^^^^^^^^^^\n  File \"/srv/conda/envs/notebook/lib/python3.12/site-packages/aiida/schedulers/scheduler.py\", line 361, in get_jobs\n    joblist = self._parse_joblist_output(retval, stdout, stderr)\n              ^^^^^^^^^^^^^^^^^^^^^^^^^^^^^^^^^^^^^^^^^^^^^^^^^^\n  File \"/srv/conda/envs/notebook/lib/python3.12/site-packages/aiida/schedulers/plugins/direct.py\", line 253, in _parse_joblist_output\n    this_job.wallclock_time_seconds = self._convert_time(job[3])\n                                                         ~~~^^^\nIndexError: list index out of range\n03/22/2025 08:34:37 AM <193> aiida.orm.nodes.process.calculation.calcjob.CalcJobNode: [ERROR] iteration 1 of do_update excepted, retrying after 20 seconds\nTraceback (most recent call last):\n  File \"/srv/conda/envs/notebook/lib/python3.12/site-packages/aiida/engine/utils.py\", line 205, in exponential_backoff_retry\n    result = await coro()\n             ^^^^^^^^^^^^\n  File \"/srv/conda/envs/notebook/lib/python3.12/site-packages/aiida/engine/processes/calcjobs/tasks.py\", line 195, in do_update\n    job_info = await cancellable.with_interrupt(update_request)\n               ^^^^^^^^^^^^^^^^^^^^^^^^^^^^^^^^^^^^^^^^^^^^^^^^\n  File \"/srv/conda/envs/notebook/lib/python3.12/site-packages/aiida/engine/utils.py\", line 115, in with_interrupt\n    result = await next(wait_iter)\n             ^^^^^^^^^^^^^^^^^^^^^\n  File \"/srv/conda/envs/notebook/lib/python3.12/asyncio/tasks.py\", line 631, in _wait_for_one\n    return f.result()  # May raise f.exception().\n           ^^^^^^^^^^\n  File \"/srv/conda/envs/notebook/lib/python3.12/asyncio/futures.py\", line 202, in result\n    raise self._exception.with_traceback(self._exception_tb)\n  File \"/srv/conda/envs/notebook/lib/python3.12/site-packages/aiida/engine/processes/calcjobs/manager.py\", line 132, in _update_job_info\n    self._jobs_cache = await self._get_jobs_from_scheduler()\n                       ^^^^^^^^^^^^^^^^^^^^^^^^^^^^^^^^^^^^^\n  File \"/srv/conda/envs/notebook/lib/python3.12/site-packages/aiida/engine/processes/calcjobs/manager.py\", line 109, in _get_jobs_from_scheduler\n    scheduler_response = scheduler.get_jobs(**kwargs)\n                         ^^^^^^^^^^^^^^^^^^^^^^^^^^^^\n  File \"/srv/conda/envs/notebook/lib/python3.12/site-packages/aiida/schedulers/plugins/direct.py\", line 269, in get_jobs\n    job_stats = super().get_jobs(jobs=jobs, user=user, as_dict=as_dict)\n                ^^^^^^^^^^^^^^^^^^^^^^^^^^^^^^^^^^^^^^^^^^^^^^^^^^^^^^^\n  File \"/srv/conda/envs/notebook/lib/python3.12/site-packages/aiida/schedulers/scheduler.py\", line 361, in get_jobs\n    joblist = self._parse_joblist_output(retval, stdout, stderr)\n              ^^^^^^^^^^^^^^^^^^^^^^^^^^^^^^^^^^^^^^^^^^^^^^^^^^\n  File \"/srv/conda/envs/notebook/lib/python3.12/site-packages/aiida/schedulers/plugins/direct.py\", line 253, in _parse_joblist_output\n    this_job.wallclock_time_seconds = self._convert_time(job[3])\n                                                         ~~~^^^\nIndexError: list index out of range\n03/22/2025 08:34:37 AM <193> aiida.orm.nodes.process.calculation.calcjob.CalcJobNode: [ERROR] iteration 1 of do_update excepted, retrying after 20 seconds\nTraceback (most recent call last):\n  File \"/srv/conda/envs/notebook/lib/python3.12/site-packages/aiida/engine/utils.py\", line 205, in exponential_backoff_retry\n    result = await coro()\n             ^^^^^^^^^^^^\n  File \"/srv/conda/envs/notebook/lib/python3.12/site-packages/aiida/engine/processes/calcjobs/tasks.py\", line 195, in do_update\n    job_info = await cancellable.with_interrupt(update_request)\n               ^^^^^^^^^^^^^^^^^^^^^^^^^^^^^^^^^^^^^^^^^^^^^^^^\n  File \"/srv/conda/envs/notebook/lib/python3.12/site-packages/aiida/engine/utils.py\", line 115, in with_interrupt\n    result = await next(wait_iter)\n             ^^^^^^^^^^^^^^^^^^^^^\n  File \"/srv/conda/envs/notebook/lib/python3.12/asyncio/tasks.py\", line 631, in _wait_for_one\n    return f.result()  # May raise f.exception().\n           ^^^^^^^^^^\n  File \"/srv/conda/envs/notebook/lib/python3.12/asyncio/futures.py\", line 202, in result\n    raise self._exception.with_traceback(self._exception_tb)\n  File \"/srv/conda/envs/notebook/lib/python3.12/site-packages/aiida/engine/processes/calcjobs/manager.py\", line 132, in _update_job_info\n    self._jobs_cache = await self._get_jobs_from_scheduler()\n                       ^^^^^^^^^^^^^^^^^^^^^^^^^^^^^^^^^^^^^\n  File \"/srv/conda/envs/notebook/lib/python3.12/site-packages/aiida/engine/processes/calcjobs/manager.py\", line 109, in _get_jobs_from_scheduler\n    scheduler_response = scheduler.get_jobs(**kwargs)\n                         ^^^^^^^^^^^^^^^^^^^^^^^^^^^^\n  File \"/srv/conda/envs/notebook/lib/python3.12/site-packages/aiida/schedulers/plugins/direct.py\", line 269, in get_jobs\n    job_stats = super().get_jobs(jobs=jobs, user=user, as_dict=as_dict)\n                ^^^^^^^^^^^^^^^^^^^^^^^^^^^^^^^^^^^^^^^^^^^^^^^^^^^^^^^\n  File \"/srv/conda/envs/notebook/lib/python3.12/site-packages/aiida/schedulers/scheduler.py\", line 361, in get_jobs\n    joblist = self._parse_joblist_output(retval, stdout, stderr)\n              ^^^^^^^^^^^^^^^^^^^^^^^^^^^^^^^^^^^^^^^^^^^^^^^^^^\n  File \"/srv/conda/envs/notebook/lib/python3.12/site-packages/aiida/schedulers/plugins/direct.py\", line 253, in _parse_joblist_output\n    this_job.wallclock_time_seconds = self._convert_time(job[3])\n                                                         ~~~^^^\nIndexError: list index out of range\n03/22/2025 08:34:37 AM <193> aiida.orm.nodes.process.calculation.calcjob.CalcJobNode: [ERROR] iteration 1 of do_update excepted, retrying after 20 seconds\nTraceback (most recent call last):\n  File \"/srv/conda/envs/notebook/lib/python3.12/site-packages/aiida/engine/utils.py\", line 205, in exponential_backoff_retry\n    result = await coro()\n             ^^^^^^^^^^^^\n  File \"/srv/conda/envs/notebook/lib/python3.12/site-packages/aiida/engine/processes/calcjobs/tasks.py\", line 195, in do_update\n    job_info = await cancellable.with_interrupt(update_request)\n               ^^^^^^^^^^^^^^^^^^^^^^^^^^^^^^^^^^^^^^^^^^^^^^^^\n  File \"/srv/conda/envs/notebook/lib/python3.12/site-packages/aiida/engine/utils.py\", line 115, in with_interrupt\n    result = await next(wait_iter)\n             ^^^^^^^^^^^^^^^^^^^^^\n  File \"/srv/conda/envs/notebook/lib/python3.12/asyncio/tasks.py\", line 631, in _wait_for_one\n    return f.result()  # May raise f.exception().\n           ^^^^^^^^^^\n  File \"/srv/conda/envs/notebook/lib/python3.12/asyncio/futures.py\", line 202, in result\n    raise self._exception.with_traceback(self._exception_tb)\n  File \"/srv/conda/envs/notebook/lib/python3.12/site-packages/aiida/engine/processes/calcjobs/manager.py\", line 132, in _update_job_info\n    self._jobs_cache = await self._get_jobs_from_scheduler()\n                       ^^^^^^^^^^^^^^^^^^^^^^^^^^^^^^^^^^^^^\n  File \"/srv/conda/envs/notebook/lib/python3.12/site-packages/aiida/engine/processes/calcjobs/manager.py\", line 109, in _get_jobs_from_scheduler\n    scheduler_response = scheduler.get_jobs(**kwargs)\n                         ^^^^^^^^^^^^^^^^^^^^^^^^^^^^\n  File \"/srv/conda/envs/notebook/lib/python3.12/site-packages/aiida/schedulers/plugins/direct.py\", line 269, in get_jobs\n    job_stats = super().get_jobs(jobs=jobs, user=user, as_dict=as_dict)\n                ^^^^^^^^^^^^^^^^^^^^^^^^^^^^^^^^^^^^^^^^^^^^^^^^^^^^^^^\n  File \"/srv/conda/envs/notebook/lib/python3.12/site-packages/aiida/schedulers/scheduler.py\", line 361, in get_jobs\n    joblist = self._parse_joblist_output(retval, stdout, stderr)\n              ^^^^^^^^^^^^^^^^^^^^^^^^^^^^^^^^^^^^^^^^^^^^^^^^^^\n  File \"/srv/conda/envs/notebook/lib/python3.12/site-packages/aiida/schedulers/plugins/direct.py\", line 253, in _parse_joblist_output\n    this_job.wallclock_time_seconds = self._convert_time(job[3])\n                                                         ~~~^^^\nIndexError: list index out of range\n03/22/2025 08:34:37 AM <193> aiida.orm.nodes.process.calculation.calcjob.CalcJobNode: [ERROR] iteration 1 of do_update excepted, retrying after 20 seconds\nTraceback (most recent call last):\n  File \"/srv/conda/envs/notebook/lib/python3.12/site-packages/aiida/engine/utils.py\", line 205, in exponential_backoff_retry\n    result = await coro()\n             ^^^^^^^^^^^^\n  File \"/srv/conda/envs/notebook/lib/python3.12/site-packages/aiida/engine/processes/calcjobs/tasks.py\", line 195, in do_update\n    job_info = await cancellable.with_interrupt(update_request)\n               ^^^^^^^^^^^^^^^^^^^^^^^^^^^^^^^^^^^^^^^^^^^^^^^^\n  File \"/srv/conda/envs/notebook/lib/python3.12/site-packages/aiida/engine/utils.py\", line 115, in with_interrupt\n    result = await next(wait_iter)\n             ^^^^^^^^^^^^^^^^^^^^^\n  File \"/srv/conda/envs/notebook/lib/python3.12/asyncio/tasks.py\", line 631, in _wait_for_one\n    return f.result()  # May raise f.exception().\n           ^^^^^^^^^^\n  File \"/srv/conda/envs/notebook/lib/python3.12/asyncio/futures.py\", line 202, in result\n    raise self._exception.with_traceback(self._exception_tb)\n  File \"/srv/conda/envs/notebook/lib/python3.12/site-packages/aiida/engine/processes/calcjobs/manager.py\", line 132, in _update_job_info\n    self._jobs_cache = await self._get_jobs_from_scheduler()\n                       ^^^^^^^^^^^^^^^^^^^^^^^^^^^^^^^^^^^^^\n  File \"/srv/conda/envs/notebook/lib/python3.12/site-packages/aiida/engine/processes/calcjobs/manager.py\", line 109, in _get_jobs_from_scheduler\n    scheduler_response = scheduler.get_jobs(**kwargs)\n                         ^^^^^^^^^^^^^^^^^^^^^^^^^^^^\n  File \"/srv/conda/envs/notebook/lib/python3.12/site-packages/aiida/schedulers/plugins/direct.py\", line 269, in get_jobs\n    job_stats = super().get_jobs(jobs=jobs, user=user, as_dict=as_dict)\n                ^^^^^^^^^^^^^^^^^^^^^^^^^^^^^^^^^^^^^^^^^^^^^^^^^^^^^^^\n  File \"/srv/conda/envs/notebook/lib/python3.12/site-packages/aiida/schedulers/scheduler.py\", line 361, in get_jobs\n    joblist = self._parse_joblist_output(retval, stdout, stderr)\n              ^^^^^^^^^^^^^^^^^^^^^^^^^^^^^^^^^^^^^^^^^^^^^^^^^^\n  File \"/srv/conda/envs/notebook/lib/python3.12/site-packages/aiida/schedulers/plugins/direct.py\", line 253, in _parse_joblist_output\n    this_job.wallclock_time_seconds = self._convert_time(job[3])\n                                                         ~~~^^^\nIndexError: list index out of range\n03/22/2025 08:34:57 AM <193> aiida.scheduler.direct: [WARNING] Unrecognized job_state 'p' for job id Activating\n03/22/2025 08:34:57 AM <193> aiida.engine.transports: [ERROR] Exception whilst using transport:\nTraceback (most recent call last):\n  File \"/srv/conda/envs/notebook/lib/python3.12/site-packages/aiida/engine/transports.py\", line 106, in request_transport\n    yield transport_request.future\n  File \"/srv/conda/envs/notebook/lib/python3.12/site-packages/aiida/engine/processes/calcjobs/manager.py\", line 109, in _get_jobs_from_scheduler\n    scheduler_response = scheduler.get_jobs(**kwargs)\n                         ^^^^^^^^^^^^^^^^^^^^^^^^^^^^\n  File \"/srv/conda/envs/notebook/lib/python3.12/site-packages/aiida/schedulers/plugins/direct.py\", line 269, in get_jobs\n    job_stats = super().get_jobs(jobs=jobs, user=user, as_dict=as_dict)\n                ^^^^^^^^^^^^^^^^^^^^^^^^^^^^^^^^^^^^^^^^^^^^^^^^^^^^^^^\n  File \"/srv/conda/envs/notebook/lib/python3.12/site-packages/aiida/schedulers/scheduler.py\", line 361, in get_jobs\n    joblist = self._parse_joblist_output(retval, stdout, stderr)\n              ^^^^^^^^^^^^^^^^^^^^^^^^^^^^^^^^^^^^^^^^^^^^^^^^^^\n  File \"/srv/conda/envs/notebook/lib/python3.12/site-packages/aiida/schedulers/plugins/direct.py\", line 253, in _parse_joblist_output\n    this_job.wallclock_time_seconds = self._convert_time(job[3])\n                                                         ~~~^^^\nIndexError: list index out of range\n\nTask exception was never retrieved\nfuture: <Task finished name='Task-63' coro=<JobsList._ensure_updating.<locals>.updating() done, defined at /srv/conda/envs/notebook/lib/python3.12/site-packages/aiida/engine/processes/calcjobs/manager.py:179> exception=IndexError('list index out of range')>\nTraceback (most recent call last):\n  File \"/srv/conda/envs/notebook/lib/python3.12/asyncio/tasks.py\", line 314, in __step_run_and_handle_result\n    result = coro.send(None)\n             ^^^^^^^^^^^^^^^\n  File \"/srv/conda/envs/notebook/lib/python3.12/site-packages/aiida/engine/processes/calcjobs/manager.py\", line 181, in updating\n    await self._update_job_info()\n  File \"/srv/conda/envs/notebook/lib/python3.12/site-packages/aiida/engine/processes/calcjobs/manager.py\", line 132, in _update_job_info\n    self._jobs_cache = await self._get_jobs_from_scheduler()\n                       ^^^^^^^^^^^^^^^^^^^^^^^^^^^^^^^^^^^^^\n  File \"/srv/conda/envs/notebook/lib/python3.12/site-packages/aiida/engine/processes/calcjobs/manager.py\", line 109, in _get_jobs_from_scheduler\n    scheduler_response = scheduler.get_jobs(**kwargs)\n                         ^^^^^^^^^^^^^^^^^^^^^^^^^^^^\n  File \"/srv/conda/envs/notebook/lib/python3.12/site-packages/aiida/schedulers/plugins/direct.py\", line 269, in get_jobs\n    job_stats = super().get_jobs(jobs=jobs, user=user, as_dict=as_dict)\n                ^^^^^^^^^^^^^^^^^^^^^^^^^^^^^^^^^^^^^^^^^^^^^^^^^^^^^^^\n  File \"/srv/conda/envs/notebook/lib/python3.12/site-packages/aiida/schedulers/scheduler.py\", line 361, in get_jobs\n    joblist = self._parse_joblist_output(retval, stdout, stderr)\n              ^^^^^^^^^^^^^^^^^^^^^^^^^^^^^^^^^^^^^^^^^^^^^^^^^^\n  File \"/srv/conda/envs/notebook/lib/python3.12/site-packages/aiida/schedulers/plugins/direct.py\", line 253, in _parse_joblist_output\n    this_job.wallclock_time_seconds = self._convert_time(job[3])\n                                                         ~~~^^^\nIndexError: list index out of range\n03/22/2025 08:34:57 AM <193> aiida.orm.nodes.process.calculation.calcjob.CalcJobNode: [ERROR] iteration 2 of do_update excepted, retrying after 40 seconds\nTraceback (most recent call last):\n  File \"/srv/conda/envs/notebook/lib/python3.12/site-packages/aiida/engine/utils.py\", line 205, in exponential_backoff_retry\n    result = await coro()\n             ^^^^^^^^^^^^\n  File \"/srv/conda/envs/notebook/lib/python3.12/site-packages/aiida/engine/processes/calcjobs/tasks.py\", line 195, in do_update\n    job_info = await cancellable.with_interrupt(update_request)\n               ^^^^^^^^^^^^^^^^^^^^^^^^^^^^^^^^^^^^^^^^^^^^^^^^\n  File \"/srv/conda/envs/notebook/lib/python3.12/site-packages/aiida/engine/utils.py\", line 115, in with_interrupt\n    result = await next(wait_iter)\n             ^^^^^^^^^^^^^^^^^^^^^\n  File \"/srv/conda/envs/notebook/lib/python3.12/asyncio/tasks.py\", line 631, in _wait_for_one\n    return f.result()  # May raise f.exception().\n           ^^^^^^^^^^\n  File \"/srv/conda/envs/notebook/lib/python3.12/asyncio/futures.py\", line 202, in result\n    raise self._exception.with_traceback(self._exception_tb)\n  File \"/srv/conda/envs/notebook/lib/python3.12/site-packages/aiida/engine/processes/calcjobs/manager.py\", line 132, in _update_job_info\n    self._jobs_cache = await self._get_jobs_from_scheduler()\n                       ^^^^^^^^^^^^^^^^^^^^^^^^^^^^^^^^^^^^^\n  File \"/srv/conda/envs/notebook/lib/python3.12/site-packages/aiida/engine/processes/calcjobs/manager.py\", line 109, in _get_jobs_from_scheduler\n    scheduler_response = scheduler.get_jobs(**kwargs)\n                         ^^^^^^^^^^^^^^^^^^^^^^^^^^^^\n  File \"/srv/conda/envs/notebook/lib/python3.12/site-packages/aiida/schedulers/plugins/direct.py\", line 269, in get_jobs\n    job_stats = super().get_jobs(jobs=jobs, user=user, as_dict=as_dict)\n                ^^^^^^^^^^^^^^^^^^^^^^^^^^^^^^^^^^^^^^^^^^^^^^^^^^^^^^^\n  File \"/srv/conda/envs/notebook/lib/python3.12/site-packages/aiida/schedulers/scheduler.py\", line 361, in get_jobs\n    joblist = self._parse_joblist_output(retval, stdout, stderr)\n              ^^^^^^^^^^^^^^^^^^^^^^^^^^^^^^^^^^^^^^^^^^^^^^^^^^\n  File \"/srv/conda/envs/notebook/lib/python3.12/site-packages/aiida/schedulers/plugins/direct.py\", line 253, in _parse_joblist_output\n    this_job.wallclock_time_seconds = self._convert_time(job[3])\n                                                         ~~~^^^\nIndexError: list index out of range\n03/22/2025 08:34:57 AM <193> aiida.scheduler.direct: [WARNING] Unrecognized job_state 'p' for job id Activating\n03/22/2025 08:34:57 AM <193> aiida.engine.transports: [ERROR] Exception whilst using transport:\nTraceback (most recent call last):\n  File \"/srv/conda/envs/notebook/lib/python3.12/site-packages/aiida/engine/transports.py\", line 106, in request_transport\n    yield transport_request.future\n  File \"/srv/conda/envs/notebook/lib/python3.12/site-packages/aiida/engine/processes/calcjobs/manager.py\", line 109, in _get_jobs_from_scheduler\n    scheduler_response = scheduler.get_jobs(**kwargs)\n                         ^^^^^^^^^^^^^^^^^^^^^^^^^^^^\n  File \"/srv/conda/envs/notebook/lib/python3.12/site-packages/aiida/schedulers/plugins/direct.py\", line 269, in get_jobs\n    job_stats = super().get_jobs(jobs=jobs, user=user, as_dict=as_dict)\n                ^^^^^^^^^^^^^^^^^^^^^^^^^^^^^^^^^^^^^^^^^^^^^^^^^^^^^^^\n  File \"/srv/conda/envs/notebook/lib/python3.12/site-packages/aiida/schedulers/scheduler.py\", line 361, in get_jobs\n    joblist = self._parse_joblist_output(retval, stdout, stderr)\n              ^^^^^^^^^^^^^^^^^^^^^^^^^^^^^^^^^^^^^^^^^^^^^^^^^^\n  File \"/srv/conda/envs/notebook/lib/python3.12/site-packages/aiida/schedulers/plugins/direct.py\", line 253, in _parse_joblist_output\n    this_job.wallclock_time_seconds = self._convert_time(job[3])\n                                                         ~~~^^^\nIndexError: list index out of range\n\nTask exception was never retrieved\nfuture: <Task finished name='Task-64' coro=<JobsList._ensure_updating.<locals>.updating() done, defined at /srv/conda/envs/notebook/lib/python3.12/site-packages/aiida/engine/processes/calcjobs/manager.py:179> exception=IndexError('list index out of range')>\nTraceback (most recent call last):\n  File \"/srv/conda/envs/notebook/lib/python3.12/asyncio/tasks.py\", line 314, in __step_run_and_handle_result\n    result = coro.send(None)\n             ^^^^^^^^^^^^^^^\n  File \"/srv/conda/envs/notebook/lib/python3.12/site-packages/aiida/engine/processes/calcjobs/manager.py\", line 181, in updating\n    await self._update_job_info()\n  File \"/srv/conda/envs/notebook/lib/python3.12/site-packages/aiida/engine/processes/calcjobs/manager.py\", line 132, in _update_job_info\n    self._jobs_cache = await self._get_jobs_from_scheduler()\n                       ^^^^^^^^^^^^^^^^^^^^^^^^^^^^^^^^^^^^^\n  File \"/srv/conda/envs/notebook/lib/python3.12/site-packages/aiida/engine/processes/calcjobs/manager.py\", line 109, in _get_jobs_from_scheduler\n    scheduler_response = scheduler.get_jobs(**kwargs)\n                         ^^^^^^^^^^^^^^^^^^^^^^^^^^^^\n  File \"/srv/conda/envs/notebook/lib/python3.12/site-packages/aiida/schedulers/plugins/direct.py\", line 269, in get_jobs\n    job_stats = super().get_jobs(jobs=jobs, user=user, as_dict=as_dict)\n                ^^^^^^^^^^^^^^^^^^^^^^^^^^^^^^^^^^^^^^^^^^^^^^^^^^^^^^^\n  File \"/srv/conda/envs/notebook/lib/python3.12/site-packages/aiida/schedulers/scheduler.py\", line 361, in get_jobs\n    joblist = self._parse_joblist_output(retval, stdout, stderr)\n              ^^^^^^^^^^^^^^^^^^^^^^^^^^^^^^^^^^^^^^^^^^^^^^^^^^\n  File \"/srv/conda/envs/notebook/lib/python3.12/site-packages/aiida/schedulers/plugins/direct.py\", line 253, in _parse_joblist_output\n    this_job.wallclock_time_seconds = self._convert_time(job[3])\n                                                         ~~~^^^\nIndexError: list index out of range\n03/22/2025 08:34:57 AM <193> aiida.orm.nodes.process.calculation.calcjob.CalcJobNode: [ERROR] iteration 2 of do_update excepted, retrying after 40 seconds\nTraceback (most recent call last):\n  File \"/srv/conda/envs/notebook/lib/python3.12/site-packages/aiida/engine/utils.py\", line 205, in exponential_backoff_retry\n    result = await coro()\n             ^^^^^^^^^^^^\n  File \"/srv/conda/envs/notebook/lib/python3.12/site-packages/aiida/engine/processes/calcjobs/tasks.py\", line 195, in do_update\n    job_info = await cancellable.with_interrupt(update_request)\n               ^^^^^^^^^^^^^^^^^^^^^^^^^^^^^^^^^^^^^^^^^^^^^^^^\n  File \"/srv/conda/envs/notebook/lib/python3.12/site-packages/aiida/engine/utils.py\", line 115, in with_interrupt\n    result = await next(wait_iter)\n             ^^^^^^^^^^^^^^^^^^^^^\n  File \"/srv/conda/envs/notebook/lib/python3.12/asyncio/tasks.py\", line 631, in _wait_for_one\n    return f.result()  # May raise f.exception().\n           ^^^^^^^^^^\n  File \"/srv/conda/envs/notebook/lib/python3.12/asyncio/futures.py\", line 202, in result\n    raise self._exception.with_traceback(self._exception_tb)\n  File \"/srv/conda/envs/notebook/lib/python3.12/site-packages/aiida/engine/processes/calcjobs/manager.py\", line 132, in _update_job_info\n    self._jobs_cache = await self._get_jobs_from_scheduler()\n                       ^^^^^^^^^^^^^^^^^^^^^^^^^^^^^^^^^^^^^\n  File \"/srv/conda/envs/notebook/lib/python3.12/site-packages/aiida/engine/processes/calcjobs/manager.py\", line 109, in _get_jobs_from_scheduler\n    scheduler_response = scheduler.get_jobs(**kwargs)\n                         ^^^^^^^^^^^^^^^^^^^^^^^^^^^^\n  File \"/srv/conda/envs/notebook/lib/python3.12/site-packages/aiida/schedulers/plugins/direct.py\", line 269, in get_jobs\n    job_stats = super().get_jobs(jobs=jobs, user=user, as_dict=as_dict)\n                ^^^^^^^^^^^^^^^^^^^^^^^^^^^^^^^^^^^^^^^^^^^^^^^^^^^^^^^\n  File \"/srv/conda/envs/notebook/lib/python3.12/site-packages/aiida/schedulers/scheduler.py\", line 361, in get_jobs\n    joblist = self._parse_joblist_output(retval, stdout, stderr)\n              ^^^^^^^^^^^^^^^^^^^^^^^^^^^^^^^^^^^^^^^^^^^^^^^^^^\n  File \"/srv/conda/envs/notebook/lib/python3.12/site-packages/aiida/schedulers/plugins/direct.py\", line 253, in _parse_joblist_output\n    this_job.wallclock_time_seconds = self._convert_time(job[3])\n                                                         ~~~^^^\nIndexError: list index out of range\n03/22/2025 08:34:57 AM <193> aiida.orm.nodes.process.calculation.calcjob.CalcJobNode: [ERROR] iteration 2 of do_update excepted, retrying after 40 seconds\nTraceback (most recent call last):\n  File \"/srv/conda/envs/notebook/lib/python3.12/site-packages/aiida/engine/utils.py\", line 205, in exponential_backoff_retry\n    result = await coro()\n             ^^^^^^^^^^^^\n  File \"/srv/conda/envs/notebook/lib/python3.12/site-packages/aiida/engine/processes/calcjobs/tasks.py\", line 195, in do_update\n    job_info = await cancellable.with_interrupt(update_request)\n               ^^^^^^^^^^^^^^^^^^^^^^^^^^^^^^^^^^^^^^^^^^^^^^^^\n  File \"/srv/conda/envs/notebook/lib/python3.12/site-packages/aiida/engine/utils.py\", line 115, in with_interrupt\n    result = await next(wait_iter)\n             ^^^^^^^^^^^^^^^^^^^^^\n  File \"/srv/conda/envs/notebook/lib/python3.12/asyncio/tasks.py\", line 631, in _wait_for_one\n    return f.result()  # May raise f.exception().\n           ^^^^^^^^^^\n  File \"/srv/conda/envs/notebook/lib/python3.12/asyncio/futures.py\", line 202, in result\n    raise self._exception.with_traceback(self._exception_tb)\n  File \"/srv/conda/envs/notebook/lib/python3.12/site-packages/aiida/engine/processes/calcjobs/manager.py\", line 132, in _update_job_info\n    self._jobs_cache = await self._get_jobs_from_scheduler()\n                       ^^^^^^^^^^^^^^^^^^^^^^^^^^^^^^^^^^^^^\n  File \"/srv/conda/envs/notebook/lib/python3.12/site-packages/aiida/engine/processes/calcjobs/manager.py\", line 109, in _get_jobs_from_scheduler\n    scheduler_response = scheduler.get_jobs(**kwargs)\n                         ^^^^^^^^^^^^^^^^^^^^^^^^^^^^\n  File \"/srv/conda/envs/notebook/lib/python3.12/site-packages/aiida/schedulers/plugins/direct.py\", line 269, in get_jobs\n    job_stats = super().get_jobs(jobs=jobs, user=user, as_dict=as_dict)\n                ^^^^^^^^^^^^^^^^^^^^^^^^^^^^^^^^^^^^^^^^^^^^^^^^^^^^^^^\n  File \"/srv/conda/envs/notebook/lib/python3.12/site-packages/aiida/schedulers/scheduler.py\", line 361, in get_jobs\n    joblist = self._parse_joblist_output(retval, stdout, stderr)\n              ^^^^^^^^^^^^^^^^^^^^^^^^^^^^^^^^^^^^^^^^^^^^^^^^^^\n  File \"/srv/conda/envs/notebook/lib/python3.12/site-packages/aiida/schedulers/plugins/direct.py\", line 253, in _parse_joblist_output\n    this_job.wallclock_time_seconds = self._convert_time(job[3])\n                                                         ~~~^^^\nIndexError: list index out of range\n03/22/2025 08:34:57 AM <193> aiida.orm.nodes.process.calculation.calcjob.CalcJobNode: [ERROR] iteration 2 of do_update excepted, retrying after 40 seconds\nTraceback (most recent call last):\n  File \"/srv/conda/envs/notebook/lib/python3.12/site-packages/aiida/engine/utils.py\", line 205, in exponential_backoff_retry\n    result = await coro()\n             ^^^^^^^^^^^^\n  File \"/srv/conda/envs/notebook/lib/python3.12/site-packages/aiida/engine/processes/calcjobs/tasks.py\", line 195, in do_update\n    job_info = await cancellable.with_interrupt(update_request)\n               ^^^^^^^^^^^^^^^^^^^^^^^^^^^^^^^^^^^^^^^^^^^^^^^^\n  File \"/srv/conda/envs/notebook/lib/python3.12/site-packages/aiida/engine/utils.py\", line 115, in with_interrupt\n    result = await next(wait_iter)\n             ^^^^^^^^^^^^^^^^^^^^^\n  File \"/srv/conda/envs/notebook/lib/python3.12/asyncio/tasks.py\", line 631, in _wait_for_one\n    return f.result()  # May raise f.exception().\n           ^^^^^^^^^^\n  File \"/srv/conda/envs/notebook/lib/python3.12/asyncio/futures.py\", line 202, in result\n    raise self._exception.with_traceback(self._exception_tb)\n  File \"/srv/conda/envs/notebook/lib/python3.12/site-packages/aiida/engine/processes/calcjobs/manager.py\", line 132, in _update_job_info\n    self._jobs_cache = await self._get_jobs_from_scheduler()\n                       ^^^^^^^^^^^^^^^^^^^^^^^^^^^^^^^^^^^^^\n  File \"/srv/conda/envs/notebook/lib/python3.12/site-packages/aiida/engine/processes/calcjobs/manager.py\", line 109, in _get_jobs_from_scheduler\n    scheduler_response = scheduler.get_jobs(**kwargs)\n                         ^^^^^^^^^^^^^^^^^^^^^^^^^^^^\n  File \"/srv/conda/envs/notebook/lib/python3.12/site-packages/aiida/schedulers/plugins/direct.py\", line 269, in get_jobs\n    job_stats = super().get_jobs(jobs=jobs, user=user, as_dict=as_dict)\n                ^^^^^^^^^^^^^^^^^^^^^^^^^^^^^^^^^^^^^^^^^^^^^^^^^^^^^^^\n  File \"/srv/conda/envs/notebook/lib/python3.12/site-packages/aiida/schedulers/scheduler.py\", line 361, in get_jobs\n    joblist = self._parse_joblist_output(retval, stdout, stderr)\n              ^^^^^^^^^^^^^^^^^^^^^^^^^^^^^^^^^^^^^^^^^^^^^^^^^^\n  File \"/srv/conda/envs/notebook/lib/python3.12/site-packages/aiida/schedulers/plugins/direct.py\", line 253, in _parse_joblist_output\n    this_job.wallclock_time_seconds = self._convert_time(job[3])\n                                                         ~~~^^^\nIndexError: list index out of range\n03/22/2025 08:34:57 AM <193> aiida.orm.nodes.process.calculation.calcjob.CalcJobNode: [ERROR] iteration 2 of do_update excepted, retrying after 40 seconds\nTraceback (most recent call last):\n  File \"/srv/conda/envs/notebook/lib/python3.12/site-packages/aiida/engine/utils.py\", line 205, in exponential_backoff_retry\n    result = await coro()\n             ^^^^^^^^^^^^\n  File \"/srv/conda/envs/notebook/lib/python3.12/site-packages/aiida/engine/processes/calcjobs/tasks.py\", line 195, in do_update\n    job_info = await cancellable.with_interrupt(update_request)\n               ^^^^^^^^^^^^^^^^^^^^^^^^^^^^^^^^^^^^^^^^^^^^^^^^\n  File \"/srv/conda/envs/notebook/lib/python3.12/site-packages/aiida/engine/utils.py\", line 115, in with_interrupt\n    result = await next(wait_iter)\n             ^^^^^^^^^^^^^^^^^^^^^\n  File \"/srv/conda/envs/notebook/lib/python3.12/asyncio/tasks.py\", line 631, in _wait_for_one\n    return f.result()  # May raise f.exception().\n           ^^^^^^^^^^\n  File \"/srv/conda/envs/notebook/lib/python3.12/asyncio/futures.py\", line 202, in result\n    raise self._exception.with_traceback(self._exception_tb)\n  File \"/srv/conda/envs/notebook/lib/python3.12/site-packages/aiida/engine/processes/calcjobs/manager.py\", line 132, in _update_job_info\n    self._jobs_cache = await self._get_jobs_from_scheduler()\n                       ^^^^^^^^^^^^^^^^^^^^^^^^^^^^^^^^^^^^^\n  File \"/srv/conda/envs/notebook/lib/python3.12/site-packages/aiida/engine/processes/calcjobs/manager.py\", line 109, in _get_jobs_from_scheduler\n    scheduler_response = scheduler.get_jobs(**kwargs)\n                         ^^^^^^^^^^^^^^^^^^^^^^^^^^^^\n  File \"/srv/conda/envs/notebook/lib/python3.12/site-packages/aiida/schedulers/plugins/direct.py\", line 269, in get_jobs\n    job_stats = super().get_jobs(jobs=jobs, user=user, as_dict=as_dict)\n                ^^^^^^^^^^^^^^^^^^^^^^^^^^^^^^^^^^^^^^^^^^^^^^^^^^^^^^^\n  File \"/srv/conda/envs/notebook/lib/python3.12/site-packages/aiida/schedulers/scheduler.py\", line 361, in get_jobs\n    joblist = self._parse_joblist_output(retval, stdout, stderr)\n              ^^^^^^^^^^^^^^^^^^^^^^^^^^^^^^^^^^^^^^^^^^^^^^^^^^\n  File \"/srv/conda/envs/notebook/lib/python3.12/site-packages/aiida/schedulers/plugins/direct.py\", line 253, in _parse_joblist_output\n    this_job.wallclock_time_seconds = self._convert_time(job[3])\n                                                         ~~~^^^\nIndexError: list index out of range\n03/22/2025 08:34:57 AM <193> aiida.orm.nodes.process.calculation.calcjob.CalcJobNode: [ERROR] iteration 2 of do_update excepted, retrying after 40 seconds\nTraceback (most recent call last):\n  File \"/srv/conda/envs/notebook/lib/python3.12/site-packages/aiida/engine/utils.py\", line 205, in exponential_backoff_retry\n    result = await coro()\n             ^^^^^^^^^^^^\n  File \"/srv/conda/envs/notebook/lib/python3.12/site-packages/aiida/engine/processes/calcjobs/tasks.py\", line 195, in do_update\n    job_info = await cancellable.with_interrupt(update_request)\n               ^^^^^^^^^^^^^^^^^^^^^^^^^^^^^^^^^^^^^^^^^^^^^^^^\n  File \"/srv/conda/envs/notebook/lib/python3.12/site-packages/aiida/engine/utils.py\", line 115, in with_interrupt\n    result = await next(wait_iter)\n             ^^^^^^^^^^^^^^^^^^^^^\n  File \"/srv/conda/envs/notebook/lib/python3.12/asyncio/tasks.py\", line 631, in _wait_for_one\n    return f.result()  # May raise f.exception().\n           ^^^^^^^^^^\n  File \"/srv/conda/envs/notebook/lib/python3.12/asyncio/futures.py\", line 202, in result\n    raise self._exception.with_traceback(self._exception_tb)\n  File \"/srv/conda/envs/notebook/lib/python3.12/site-packages/aiida/engine/processes/calcjobs/manager.py\", line 132, in _update_job_info\n    self._jobs_cache = await self._get_jobs_from_scheduler()\n                       ^^^^^^^^^^^^^^^^^^^^^^^^^^^^^^^^^^^^^\n  File \"/srv/conda/envs/notebook/lib/python3.12/site-packages/aiida/engine/processes/calcjobs/manager.py\", line 109, in _get_jobs_from_scheduler\n    scheduler_response = scheduler.get_jobs(**kwargs)\n                         ^^^^^^^^^^^^^^^^^^^^^^^^^^^^\n  File \"/srv/conda/envs/notebook/lib/python3.12/site-packages/aiida/schedulers/plugins/direct.py\", line 269, in get_jobs\n    job_stats = super().get_jobs(jobs=jobs, user=user, as_dict=as_dict)\n                ^^^^^^^^^^^^^^^^^^^^^^^^^^^^^^^^^^^^^^^^^^^^^^^^^^^^^^^\n  File \"/srv/conda/envs/notebook/lib/python3.12/site-packages/aiida/schedulers/scheduler.py\", line 361, in get_jobs\n    joblist = self._parse_joblist_output(retval, stdout, stderr)\n              ^^^^^^^^^^^^^^^^^^^^^^^^^^^^^^^^^^^^^^^^^^^^^^^^^^\n  File \"/srv/conda/envs/notebook/lib/python3.12/site-packages/aiida/schedulers/plugins/direct.py\", line 253, in _parse_joblist_output\n    this_job.wallclock_time_seconds = self._convert_time(job[3])\n                                                         ~~~^^^\nIndexError: list index out of range\n03/22/2025 08:34:57 AM <193> aiida.orm.nodes.process.calculation.calcjob.CalcJobNode: [ERROR] iteration 2 of do_update excepted, retrying after 40 seconds\nTraceback (most recent call last):\n  File \"/srv/conda/envs/notebook/lib/python3.12/site-packages/aiida/engine/utils.py\", line 205, in exponential_backoff_retry\n    result = await coro()\n             ^^^^^^^^^^^^\n  File \"/srv/conda/envs/notebook/lib/python3.12/site-packages/aiida/engine/processes/calcjobs/tasks.py\", line 195, in do_update\n    job_info = await cancellable.with_interrupt(update_request)\n               ^^^^^^^^^^^^^^^^^^^^^^^^^^^^^^^^^^^^^^^^^^^^^^^^\n  File \"/srv/conda/envs/notebook/lib/python3.12/site-packages/aiida/engine/utils.py\", line 115, in with_interrupt\n    result = await next(wait_iter)\n             ^^^^^^^^^^^^^^^^^^^^^\n  File \"/srv/conda/envs/notebook/lib/python3.12/asyncio/tasks.py\", line 631, in _wait_for_one\n    return f.result()  # May raise f.exception().\n           ^^^^^^^^^^\n  File \"/srv/conda/envs/notebook/lib/python3.12/asyncio/futures.py\", line 202, in result\n    raise self._exception.with_traceback(self._exception_tb)\n  File \"/srv/conda/envs/notebook/lib/python3.12/site-packages/aiida/engine/processes/calcjobs/manager.py\", line 132, in _update_job_info\n    self._jobs_cache = await self._get_jobs_from_scheduler()\n                       ^^^^^^^^^^^^^^^^^^^^^^^^^^^^^^^^^^^^^\n  File \"/srv/conda/envs/notebook/lib/python3.12/site-packages/aiida/engine/processes/calcjobs/manager.py\", line 109, in _get_jobs_from_scheduler\n    scheduler_response = scheduler.get_jobs(**kwargs)\n                         ^^^^^^^^^^^^^^^^^^^^^^^^^^^^\n  File \"/srv/conda/envs/notebook/lib/python3.12/site-packages/aiida/schedulers/plugins/direct.py\", line 269, in get_jobs\n    job_stats = super().get_jobs(jobs=jobs, user=user, as_dict=as_dict)\n                ^^^^^^^^^^^^^^^^^^^^^^^^^^^^^^^^^^^^^^^^^^^^^^^^^^^^^^^\n  File \"/srv/conda/envs/notebook/lib/python3.12/site-packages/aiida/schedulers/scheduler.py\", line 361, in get_jobs\n    joblist = self._parse_joblist_output(retval, stdout, stderr)\n              ^^^^^^^^^^^^^^^^^^^^^^^^^^^^^^^^^^^^^^^^^^^^^^^^^^\n  File \"/srv/conda/envs/notebook/lib/python3.12/site-packages/aiida/schedulers/plugins/direct.py\", line 253, in _parse_joblist_output\n    this_job.wallclock_time_seconds = self._convert_time(job[3])\n                                                         ~~~^^^\nIndexError: list index out of range\n03/22/2025 08:34:57 AM <193> aiida.orm.nodes.process.calculation.calcjob.CalcJobNode: [ERROR] iteration 2 of do_update excepted, retrying after 40 seconds\nTraceback (most recent call last):\n  File \"/srv/conda/envs/notebook/lib/python3.12/site-packages/aiida/engine/utils.py\", line 205, in exponential_backoff_retry\n    result = await coro()\n             ^^^^^^^^^^^^\n  File \"/srv/conda/envs/notebook/lib/python3.12/site-packages/aiida/engine/processes/calcjobs/tasks.py\", line 195, in do_update\n    job_info = await cancellable.with_interrupt(update_request)\n               ^^^^^^^^^^^^^^^^^^^^^^^^^^^^^^^^^^^^^^^^^^^^^^^^\n  File \"/srv/conda/envs/notebook/lib/python3.12/site-packages/aiida/engine/utils.py\", line 115, in with_interrupt\n    result = await next(wait_iter)\n             ^^^^^^^^^^^^^^^^^^^^^\n  File \"/srv/conda/envs/notebook/lib/python3.12/asyncio/tasks.py\", line 631, in _wait_for_one\n    return f.result()  # May raise f.exception().\n           ^^^^^^^^^^\n  File \"/srv/conda/envs/notebook/lib/python3.12/asyncio/futures.py\", line 202, in result\n    raise self._exception.with_traceback(self._exception_tb)\n  File \"/srv/conda/envs/notebook/lib/python3.12/site-packages/aiida/engine/processes/calcjobs/manager.py\", line 132, in _update_job_info\n    self._jobs_cache = await self._get_jobs_from_scheduler()\n                       ^^^^^^^^^^^^^^^^^^^^^^^^^^^^^^^^^^^^^\n  File \"/srv/conda/envs/notebook/lib/python3.12/site-packages/aiida/engine/processes/calcjobs/manager.py\", line 109, in _get_jobs_from_scheduler\n    scheduler_response = scheduler.get_jobs(**kwargs)\n                         ^^^^^^^^^^^^^^^^^^^^^^^^^^^^\n  File \"/srv/conda/envs/notebook/lib/python3.12/site-packages/aiida/schedulers/plugins/direct.py\", line 269, in get_jobs\n    job_stats = super().get_jobs(jobs=jobs, user=user, as_dict=as_dict)\n                ^^^^^^^^^^^^^^^^^^^^^^^^^^^^^^^^^^^^^^^^^^^^^^^^^^^^^^^\n  File \"/srv/conda/envs/notebook/lib/python3.12/site-packages/aiida/schedulers/scheduler.py\", line 361, in get_jobs\n    joblist = self._parse_joblist_output(retval, stdout, stderr)\n              ^^^^^^^^^^^^^^^^^^^^^^^^^^^^^^^^^^^^^^^^^^^^^^^^^^\n  File \"/srv/conda/envs/notebook/lib/python3.12/site-packages/aiida/schedulers/plugins/direct.py\", line 253, in _parse_joblist_output\n    this_job.wallclock_time_seconds = self._convert_time(job[3])\n                                                         ~~~^^^\nIndexError: list index out of range\n03/22/2025 08:34:57 AM <193> aiida.orm.nodes.process.calculation.calcjob.CalcJobNode: [ERROR] iteration 2 of do_update excepted, retrying after 40 seconds\nTraceback (most recent call last):\n  File \"/srv/conda/envs/notebook/lib/python3.12/site-packages/aiida/engine/utils.py\", line 205, in exponential_backoff_retry\n    result = await coro()\n             ^^^^^^^^^^^^\n  File \"/srv/conda/envs/notebook/lib/python3.12/site-packages/aiida/engine/processes/calcjobs/tasks.py\", line 195, in do_update\n    job_info = await cancellable.with_interrupt(update_request)\n               ^^^^^^^^^^^^^^^^^^^^^^^^^^^^^^^^^^^^^^^^^^^^^^^^\n  File \"/srv/conda/envs/notebook/lib/python3.12/site-packages/aiida/engine/utils.py\", line 115, in with_interrupt\n    result = await next(wait_iter)\n             ^^^^^^^^^^^^^^^^^^^^^\n  File \"/srv/conda/envs/notebook/lib/python3.12/asyncio/tasks.py\", line 631, in _wait_for_one\n    return f.result()  # May raise f.exception().\n           ^^^^^^^^^^\n  File \"/srv/conda/envs/notebook/lib/python3.12/asyncio/futures.py\", line 202, in result\n    raise self._exception.with_traceback(self._exception_tb)\n  File \"/srv/conda/envs/notebook/lib/python3.12/site-packages/aiida/engine/processes/calcjobs/manager.py\", line 132, in _update_job_info\n    self._jobs_cache = await self._get_jobs_from_scheduler()\n                       ^^^^^^^^^^^^^^^^^^^^^^^^^^^^^^^^^^^^^\n  File \"/srv/conda/envs/notebook/lib/python3.12/site-packages/aiida/engine/processes/calcjobs/manager.py\", line 109, in _get_jobs_from_scheduler\n    scheduler_response = scheduler.get_jobs(**kwargs)\n                         ^^^^^^^^^^^^^^^^^^^^^^^^^^^^\n  File \"/srv/conda/envs/notebook/lib/python3.12/site-packages/aiida/schedulers/plugins/direct.py\", line 269, in get_jobs\n    job_stats = super().get_jobs(jobs=jobs, user=user, as_dict=as_dict)\n                ^^^^^^^^^^^^^^^^^^^^^^^^^^^^^^^^^^^^^^^^^^^^^^^^^^^^^^^\n  File \"/srv/conda/envs/notebook/lib/python3.12/site-packages/aiida/schedulers/scheduler.py\", line 361, in get_jobs\n    joblist = self._parse_joblist_output(retval, stdout, stderr)\n              ^^^^^^^^^^^^^^^^^^^^^^^^^^^^^^^^^^^^^^^^^^^^^^^^^^\n  File \"/srv/conda/envs/notebook/lib/python3.12/site-packages/aiida/schedulers/plugins/direct.py\", line 253, in _parse_joblist_output\n    this_job.wallclock_time_seconds = self._convert_time(job[3])\n                                                         ~~~^^^\nIndexError: list index out of range\n03/22/2025 08:34:57 AM <193> aiida.orm.nodes.process.calculation.calcjob.CalcJobNode: [ERROR] iteration 2 of do_update excepted, retrying after 40 seconds\nTraceback (most recent call last):\n  File \"/srv/conda/envs/notebook/lib/python3.12/site-packages/aiida/engine/utils.py\", line 205, in exponential_backoff_retry\n    result = await coro()\n             ^^^^^^^^^^^^\n  File \"/srv/conda/envs/notebook/lib/python3.12/site-packages/aiida/engine/processes/calcjobs/tasks.py\", line 195, in do_update\n    job_info = await cancellable.with_interrupt(update_request)\n               ^^^^^^^^^^^^^^^^^^^^^^^^^^^^^^^^^^^^^^^^^^^^^^^^\n  File \"/srv/conda/envs/notebook/lib/python3.12/site-packages/aiida/engine/utils.py\", line 115, in with_interrupt\n    result = await next(wait_iter)\n             ^^^^^^^^^^^^^^^^^^^^^\n  File \"/srv/conda/envs/notebook/lib/python3.12/asyncio/tasks.py\", line 631, in _wait_for_one\n    return f.result()  # May raise f.exception().\n           ^^^^^^^^^^\n  File \"/srv/conda/envs/notebook/lib/python3.12/asyncio/futures.py\", line 202, in result\n    raise self._exception.with_traceback(self._exception_tb)\n  File \"/srv/conda/envs/notebook/lib/python3.12/site-packages/aiida/engine/processes/calcjobs/manager.py\", line 132, in _update_job_info\n    self._jobs_cache = await self._get_jobs_from_scheduler()\n                       ^^^^^^^^^^^^^^^^^^^^^^^^^^^^^^^^^^^^^\n  File \"/srv/conda/envs/notebook/lib/python3.12/site-packages/aiida/engine/processes/calcjobs/manager.py\", line 109, in _get_jobs_from_scheduler\n    scheduler_response = scheduler.get_jobs(**kwargs)\n                         ^^^^^^^^^^^^^^^^^^^^^^^^^^^^\n  File \"/srv/conda/envs/notebook/lib/python3.12/site-packages/aiida/schedulers/plugins/direct.py\", line 269, in get_jobs\n    job_stats = super().get_jobs(jobs=jobs, user=user, as_dict=as_dict)\n                ^^^^^^^^^^^^^^^^^^^^^^^^^^^^^^^^^^^^^^^^^^^^^^^^^^^^^^^\n  File \"/srv/conda/envs/notebook/lib/python3.12/site-packages/aiida/schedulers/scheduler.py\", line 361, in get_jobs\n    joblist = self._parse_joblist_output(retval, stdout, stderr)\n              ^^^^^^^^^^^^^^^^^^^^^^^^^^^^^^^^^^^^^^^^^^^^^^^^^^\n  File \"/srv/conda/envs/notebook/lib/python3.12/site-packages/aiida/schedulers/plugins/direct.py\", line 253, in _parse_joblist_output\n    this_job.wallclock_time_seconds = self._convert_time(job[3])\n                                                         ~~~^^^\nIndexError: list index out of range\n03/22/2025 08:34:57 AM <193> aiida.orm.nodes.process.calculation.calcjob.CalcJobNode: [ERROR] iteration 2 of do_update excepted, retrying after 40 seconds\nTraceback (most recent call last):\n  File \"/srv/conda/envs/notebook/lib/python3.12/site-packages/aiida/engine/utils.py\", line 205, in exponential_backoff_retry\n    result = await coro()\n             ^^^^^^^^^^^^\n  File \"/srv/conda/envs/notebook/lib/python3.12/site-packages/aiida/engine/processes/calcjobs/tasks.py\", line 195, in do_update\n    job_info = await cancellable.with_interrupt(update_request)\n               ^^^^^^^^^^^^^^^^^^^^^^^^^^^^^^^^^^^^^^^^^^^^^^^^\n  File \"/srv/conda/envs/notebook/lib/python3.12/site-packages/aiida/engine/utils.py\", line 115, in with_interrupt\n    result = await next(wait_iter)\n             ^^^^^^^^^^^^^^^^^^^^^\n  File \"/srv/conda/envs/notebook/lib/python3.12/asyncio/tasks.py\", line 631, in _wait_for_one\n    return f.result()  # May raise f.exception().\n           ^^^^^^^^^^\n  File \"/srv/conda/envs/notebook/lib/python3.12/asyncio/futures.py\", line 202, in result\n    raise self._exception.with_traceback(self._exception_tb)\n  File \"/srv/conda/envs/notebook/lib/python3.12/site-packages/aiida/engine/processes/calcjobs/manager.py\", line 132, in _update_job_info\n    self._jobs_cache = await self._get_jobs_from_scheduler()\n                       ^^^^^^^^^^^^^^^^^^^^^^^^^^^^^^^^^^^^^\n  File \"/srv/conda/envs/notebook/lib/python3.12/site-packages/aiida/engine/processes/calcjobs/manager.py\", line 109, in _get_jobs_from_scheduler\n    scheduler_response = scheduler.get_jobs(**kwargs)\n                         ^^^^^^^^^^^^^^^^^^^^^^^^^^^^\n  File \"/srv/conda/envs/notebook/lib/python3.12/site-packages/aiida/schedulers/plugins/direct.py\", line 269, in get_jobs\n    job_stats = super().get_jobs(jobs=jobs, user=user, as_dict=as_dict)\n                ^^^^^^^^^^^^^^^^^^^^^^^^^^^^^^^^^^^^^^^^^^^^^^^^^^^^^^^\n  File \"/srv/conda/envs/notebook/lib/python3.12/site-packages/aiida/schedulers/scheduler.py\", line 361, in get_jobs\n    joblist = self._parse_joblist_output(retval, stdout, stderr)\n              ^^^^^^^^^^^^^^^^^^^^^^^^^^^^^^^^^^^^^^^^^^^^^^^^^^\n  File \"/srv/conda/envs/notebook/lib/python3.12/site-packages/aiida/schedulers/plugins/direct.py\", line 253, in _parse_joblist_output\n    this_job.wallclock_time_seconds = self._convert_time(job[3])\n                                                         ~~~^^^\nIndexError: list index out of range\n03/22/2025 08:34:57 AM <193> aiida.orm.nodes.process.calculation.calcjob.CalcJobNode: [ERROR] iteration 2 of do_update excepted, retrying after 40 seconds\nTraceback (most recent call last):\n  File \"/srv/conda/envs/notebook/lib/python3.12/site-packages/aiida/engine/utils.py\", line 205, in exponential_backoff_retry\n    result = await coro()\n             ^^^^^^^^^^^^\n  File \"/srv/conda/envs/notebook/lib/python3.12/site-packages/aiida/engine/processes/calcjobs/tasks.py\", line 195, in do_update\n    job_info = await cancellable.with_interrupt(update_request)\n               ^^^^^^^^^^^^^^^^^^^^^^^^^^^^^^^^^^^^^^^^^^^^^^^^\n  File \"/srv/conda/envs/notebook/lib/python3.12/site-packages/aiida/engine/utils.py\", line 115, in with_interrupt\n    result = await next(wait_iter)\n             ^^^^^^^^^^^^^^^^^^^^^\n  File \"/srv/conda/envs/notebook/lib/python3.12/asyncio/tasks.py\", line 631, in _wait_for_one\n    return f.result()  # May raise f.exception().\n           ^^^^^^^^^^\n  File \"/srv/conda/envs/notebook/lib/python3.12/asyncio/futures.py\", line 202, in result\n    raise self._exception.with_traceback(self._exception_tb)\n  File \"/srv/conda/envs/notebook/lib/python3.12/site-packages/aiida/engine/processes/calcjobs/manager.py\", line 132, in _update_job_info\n    self._jobs_cache = await self._get_jobs_from_scheduler()\n                       ^^^^^^^^^^^^^^^^^^^^^^^^^^^^^^^^^^^^^\n  File \"/srv/conda/envs/notebook/lib/python3.12/site-packages/aiida/engine/processes/calcjobs/manager.py\", line 109, in _get_jobs_from_scheduler\n    scheduler_response = scheduler.get_jobs(**kwargs)\n                         ^^^^^^^^^^^^^^^^^^^^^^^^^^^^\n  File \"/srv/conda/envs/notebook/lib/python3.12/site-packages/aiida/schedulers/plugins/direct.py\", line 269, in get_jobs\n    job_stats = super().get_jobs(jobs=jobs, user=user, as_dict=as_dict)\n                ^^^^^^^^^^^^^^^^^^^^^^^^^^^^^^^^^^^^^^^^^^^^^^^^^^^^^^^\n  File \"/srv/conda/envs/notebook/lib/python3.12/site-packages/aiida/schedulers/scheduler.py\", line 361, in get_jobs\n    joblist = self._parse_joblist_output(retval, stdout, stderr)\n              ^^^^^^^^^^^^^^^^^^^^^^^^^^^^^^^^^^^^^^^^^^^^^^^^^^\n  File \"/srv/conda/envs/notebook/lib/python3.12/site-packages/aiida/schedulers/plugins/direct.py\", line 253, in _parse_joblist_output\n    this_job.wallclock_time_seconds = self._convert_time(job[3])\n                                                         ~~~^^^\nIndexError: list index out of range\n03/22/2025 08:34:57 AM <193> aiida.orm.nodes.process.calculation.calcjob.CalcJobNode: [ERROR] iteration 2 of do_update excepted, retrying after 40 seconds\nTraceback (most recent call last):\n  File \"/srv/conda/envs/notebook/lib/python3.12/site-packages/aiida/engine/utils.py\", line 205, in exponential_backoff_retry\n    result = await coro()\n             ^^^^^^^^^^^^\n  File \"/srv/conda/envs/notebook/lib/python3.12/site-packages/aiida/engine/processes/calcjobs/tasks.py\", line 195, in do_update\n    job_info = await cancellable.with_interrupt(update_request)\n               ^^^^^^^^^^^^^^^^^^^^^^^^^^^^^^^^^^^^^^^^^^^^^^^^\n  File \"/srv/conda/envs/notebook/lib/python3.12/site-packages/aiida/engine/utils.py\", line 115, in with_interrupt\n    result = await next(wait_iter)\n             ^^^^^^^^^^^^^^^^^^^^^\n  File \"/srv/conda/envs/notebook/lib/python3.12/asyncio/tasks.py\", line 631, in _wait_for_one\n    return f.result()  # May raise f.exception().\n           ^^^^^^^^^^\n  File \"/srv/conda/envs/notebook/lib/python3.12/asyncio/futures.py\", line 202, in result\n    raise self._exception.with_traceback(self._exception_tb)\n  File \"/srv/conda/envs/notebook/lib/python3.12/site-packages/aiida/engine/processes/calcjobs/manager.py\", line 132, in _update_job_info\n    self._jobs_cache = await self._get_jobs_from_scheduler()\n                       ^^^^^^^^^^^^^^^^^^^^^^^^^^^^^^^^^^^^^\n  File \"/srv/conda/envs/notebook/lib/python3.12/site-packages/aiida/engine/processes/calcjobs/manager.py\", line 109, in _get_jobs_from_scheduler\n    scheduler_response = scheduler.get_jobs(**kwargs)\n                         ^^^^^^^^^^^^^^^^^^^^^^^^^^^^\n  File \"/srv/conda/envs/notebook/lib/python3.12/site-packages/aiida/schedulers/plugins/direct.py\", line 269, in get_jobs\n    job_stats = super().get_jobs(jobs=jobs, user=user, as_dict=as_dict)\n                ^^^^^^^^^^^^^^^^^^^^^^^^^^^^^^^^^^^^^^^^^^^^^^^^^^^^^^^\n  File \"/srv/conda/envs/notebook/lib/python3.12/site-packages/aiida/schedulers/scheduler.py\", line 361, in get_jobs\n    joblist = self._parse_joblist_output(retval, stdout, stderr)\n              ^^^^^^^^^^^^^^^^^^^^^^^^^^^^^^^^^^^^^^^^^^^^^^^^^^\n  File \"/srv/conda/envs/notebook/lib/python3.12/site-packages/aiida/schedulers/plugins/direct.py\", line 253, in _parse_joblist_output\n    this_job.wallclock_time_seconds = self._convert_time(job[3])\n                                                         ~~~^^^\nIndexError: list index out of range\n03/22/2025 08:34:57 AM <193> aiida.orm.nodes.process.calculation.calcjob.CalcJobNode: [ERROR] iteration 2 of do_update excepted, retrying after 40 seconds\nTraceback (most recent call last):\n  File \"/srv/conda/envs/notebook/lib/python3.12/site-packages/aiida/engine/utils.py\", line 205, in exponential_backoff_retry\n    result = await coro()\n             ^^^^^^^^^^^^\n  File \"/srv/conda/envs/notebook/lib/python3.12/site-packages/aiida/engine/processes/calcjobs/tasks.py\", line 195, in do_update\n    job_info = await cancellable.with_interrupt(update_request)\n               ^^^^^^^^^^^^^^^^^^^^^^^^^^^^^^^^^^^^^^^^^^^^^^^^\n  File \"/srv/conda/envs/notebook/lib/python3.12/site-packages/aiida/engine/utils.py\", line 115, in with_interrupt\n    result = await next(wait_iter)\n             ^^^^^^^^^^^^^^^^^^^^^\n  File \"/srv/conda/envs/notebook/lib/python3.12/asyncio/tasks.py\", line 631, in _wait_for_one\n    return f.result()  # May raise f.exception().\n           ^^^^^^^^^^\n  File \"/srv/conda/envs/notebook/lib/python3.12/asyncio/futures.py\", line 202, in result\n    raise self._exception.with_traceback(self._exception_tb)\n  File \"/srv/conda/envs/notebook/lib/python3.12/site-packages/aiida/engine/processes/calcjobs/manager.py\", line 132, in _update_job_info\n    self._jobs_cache = await self._get_jobs_from_scheduler()\n                       ^^^^^^^^^^^^^^^^^^^^^^^^^^^^^^^^^^^^^\n  File \"/srv/conda/envs/notebook/lib/python3.12/site-packages/aiida/engine/processes/calcjobs/manager.py\", line 109, in _get_jobs_from_scheduler\n    scheduler_response = scheduler.get_jobs(**kwargs)\n                         ^^^^^^^^^^^^^^^^^^^^^^^^^^^^\n  File \"/srv/conda/envs/notebook/lib/python3.12/site-packages/aiida/schedulers/plugins/direct.py\", line 269, in get_jobs\n    job_stats = super().get_jobs(jobs=jobs, user=user, as_dict=as_dict)\n                ^^^^^^^^^^^^^^^^^^^^^^^^^^^^^^^^^^^^^^^^^^^^^^^^^^^^^^^\n  File \"/srv/conda/envs/notebook/lib/python3.12/site-packages/aiida/schedulers/scheduler.py\", line 361, in get_jobs\n    joblist = self._parse_joblist_output(retval, stdout, stderr)\n              ^^^^^^^^^^^^^^^^^^^^^^^^^^^^^^^^^^^^^^^^^^^^^^^^^^\n  File \"/srv/conda/envs/notebook/lib/python3.12/site-packages/aiida/schedulers/plugins/direct.py\", line 253, in _parse_joblist_output\n    this_job.wallclock_time_seconds = self._convert_time(job[3])\n                                                         ~~~^^^\nIndexError: list index out of range\n03/22/2025 08:34:57 AM <193> aiida.orm.nodes.process.calculation.calcjob.CalcJobNode: [ERROR] iteration 2 of do_update excepted, retrying after 40 seconds\nTraceback (most recent call last):\n  File \"/srv/conda/envs/notebook/lib/python3.12/site-packages/aiida/engine/utils.py\", line 205, in exponential_backoff_retry\n    result = await coro()\n             ^^^^^^^^^^^^\n  File \"/srv/conda/envs/notebook/lib/python3.12/site-packages/aiida/engine/processes/calcjobs/tasks.py\", line 195, in do_update\n    job_info = await cancellable.with_interrupt(update_request)\n               ^^^^^^^^^^^^^^^^^^^^^^^^^^^^^^^^^^^^^^^^^^^^^^^^\n  File \"/srv/conda/envs/notebook/lib/python3.12/site-packages/aiida/engine/utils.py\", line 115, in with_interrupt\n    result = await next(wait_iter)\n             ^^^^^^^^^^^^^^^^^^^^^\n  File \"/srv/conda/envs/notebook/lib/python3.12/asyncio/tasks.py\", line 631, in _wait_for_one\n    return f.result()  # May raise f.exception().\n           ^^^^^^^^^^\n  File \"/srv/conda/envs/notebook/lib/python3.12/asyncio/futures.py\", line 202, in result\n    raise self._exception.with_traceback(self._exception_tb)\n  File \"/srv/conda/envs/notebook/lib/python3.12/site-packages/aiida/engine/processes/calcjobs/manager.py\", line 132, in _update_job_info\n    self._jobs_cache = await self._get_jobs_from_scheduler()\n                       ^^^^^^^^^^^^^^^^^^^^^^^^^^^^^^^^^^^^^\n  File \"/srv/conda/envs/notebook/lib/python3.12/site-packages/aiida/engine/processes/calcjobs/manager.py\", line 109, in _get_jobs_from_scheduler\n    scheduler_response = scheduler.get_jobs(**kwargs)\n                         ^^^^^^^^^^^^^^^^^^^^^^^^^^^^\n  File \"/srv/conda/envs/notebook/lib/python3.12/site-packages/aiida/schedulers/plugins/direct.py\", line 269, in get_jobs\n    job_stats = super().get_jobs(jobs=jobs, user=user, as_dict=as_dict)\n                ^^^^^^^^^^^^^^^^^^^^^^^^^^^^^^^^^^^^^^^^^^^^^^^^^^^^^^^\n  File \"/srv/conda/envs/notebook/lib/python3.12/site-packages/aiida/schedulers/scheduler.py\", line 361, in get_jobs\n    joblist = self._parse_joblist_output(retval, stdout, stderr)\n              ^^^^^^^^^^^^^^^^^^^^^^^^^^^^^^^^^^^^^^^^^^^^^^^^^^\n  File \"/srv/conda/envs/notebook/lib/python3.12/site-packages/aiida/schedulers/plugins/direct.py\", line 253, in _parse_joblist_output\n    this_job.wallclock_time_seconds = self._convert_time(job[3])\n                                                         ~~~^^^\nIndexError: list index out of range\n03/22/2025 08:35:37 AM <193> aiida.scheduler.direct: [WARNING] Unrecognized job_state 'p' for job id Activating\n03/22/2025 08:35:37 AM <193> aiida.engine.transports: [ERROR] Exception whilst using transport:\nTraceback (most recent call last):\n  File \"/srv/conda/envs/notebook/lib/python3.12/site-packages/aiida/engine/transports.py\", line 106, in request_transport\n    yield transport_request.future\n  File \"/srv/conda/envs/notebook/lib/python3.12/site-packages/aiida/engine/processes/calcjobs/manager.py\", line 109, in _get_jobs_from_scheduler\n    scheduler_response = scheduler.get_jobs(**kwargs)\n                         ^^^^^^^^^^^^^^^^^^^^^^^^^^^^\n  File \"/srv/conda/envs/notebook/lib/python3.12/site-packages/aiida/schedulers/plugins/direct.py\", line 269, in get_jobs\n    job_stats = super().get_jobs(jobs=jobs, user=user, as_dict=as_dict)\n                ^^^^^^^^^^^^^^^^^^^^^^^^^^^^^^^^^^^^^^^^^^^^^^^^^^^^^^^\n  File \"/srv/conda/envs/notebook/lib/python3.12/site-packages/aiida/schedulers/scheduler.py\", line 361, in get_jobs\n    joblist = self._parse_joblist_output(retval, stdout, stderr)\n              ^^^^^^^^^^^^^^^^^^^^^^^^^^^^^^^^^^^^^^^^^^^^^^^^^^\n  File \"/srv/conda/envs/notebook/lib/python3.12/site-packages/aiida/schedulers/plugins/direct.py\", line 253, in _parse_joblist_output\n    this_job.wallclock_time_seconds = self._convert_time(job[3])\n                                                         ~~~^^^\nIndexError: list index out of range\n\nTask exception was never retrieved\nfuture: <Task finished name='Task-65' coro=<JobsList._ensure_updating.<locals>.updating() done, defined at /srv/conda/envs/notebook/lib/python3.12/site-packages/aiida/engine/processes/calcjobs/manager.py:179> exception=IndexError('list index out of range')>\nTraceback (most recent call last):\n  File \"/srv/conda/envs/notebook/lib/python3.12/asyncio/tasks.py\", line 314, in __step_run_and_handle_result\n    result = coro.send(None)\n             ^^^^^^^^^^^^^^^\n  File \"/srv/conda/envs/notebook/lib/python3.12/site-packages/aiida/engine/processes/calcjobs/manager.py\", line 181, in updating\n    await self._update_job_info()\n  File \"/srv/conda/envs/notebook/lib/python3.12/site-packages/aiida/engine/processes/calcjobs/manager.py\", line 132, in _update_job_info\n    self._jobs_cache = await self._get_jobs_from_scheduler()\n                       ^^^^^^^^^^^^^^^^^^^^^^^^^^^^^^^^^^^^^\n  File \"/srv/conda/envs/notebook/lib/python3.12/site-packages/aiida/engine/processes/calcjobs/manager.py\", line 109, in _get_jobs_from_scheduler\n    scheduler_response = scheduler.get_jobs(**kwargs)\n                         ^^^^^^^^^^^^^^^^^^^^^^^^^^^^\n  File \"/srv/conda/envs/notebook/lib/python3.12/site-packages/aiida/schedulers/plugins/direct.py\", line 269, in get_jobs\n    job_stats = super().get_jobs(jobs=jobs, user=user, as_dict=as_dict)\n                ^^^^^^^^^^^^^^^^^^^^^^^^^^^^^^^^^^^^^^^^^^^^^^^^^^^^^^^\n  File \"/srv/conda/envs/notebook/lib/python3.12/site-packages/aiida/schedulers/scheduler.py\", line 361, in get_jobs\n    joblist = self._parse_joblist_output(retval, stdout, stderr)\n              ^^^^^^^^^^^^^^^^^^^^^^^^^^^^^^^^^^^^^^^^^^^^^^^^^^\n  File \"/srv/conda/envs/notebook/lib/python3.12/site-packages/aiida/schedulers/plugins/direct.py\", line 253, in _parse_joblist_output\n    this_job.wallclock_time_seconds = self._convert_time(job[3])\n                                                         ~~~^^^\nIndexError: list index out of range\n03/22/2025 08:35:37 AM <193> aiida.orm.nodes.process.calculation.calcjob.CalcJobNode: [ERROR] iteration 3 of do_update excepted, retrying after 80 seconds\nTraceback (most recent call last):\n  File \"/srv/conda/envs/notebook/lib/python3.12/site-packages/aiida/engine/utils.py\", line 205, in exponential_backoff_retry\n    result = await coro()\n             ^^^^^^^^^^^^\n  File \"/srv/conda/envs/notebook/lib/python3.12/site-packages/aiida/engine/processes/calcjobs/tasks.py\", line 195, in do_update\n    job_info = await cancellable.with_interrupt(update_request)\n               ^^^^^^^^^^^^^^^^^^^^^^^^^^^^^^^^^^^^^^^^^^^^^^^^\n  File \"/srv/conda/envs/notebook/lib/python3.12/site-packages/aiida/engine/utils.py\", line 115, in with_interrupt\n    result = await next(wait_iter)\n             ^^^^^^^^^^^^^^^^^^^^^\n  File \"/srv/conda/envs/notebook/lib/python3.12/asyncio/tasks.py\", line 631, in _wait_for_one\n    return f.result()  # May raise f.exception().\n           ^^^^^^^^^^\n  File \"/srv/conda/envs/notebook/lib/python3.12/asyncio/futures.py\", line 202, in result\n    raise self._exception.with_traceback(self._exception_tb)\n  File \"/srv/conda/envs/notebook/lib/python3.12/site-packages/aiida/engine/processes/calcjobs/manager.py\", line 132, in _update_job_info\n    self._jobs_cache = await self._get_jobs_from_scheduler()\n                       ^^^^^^^^^^^^^^^^^^^^^^^^^^^^^^^^^^^^^\n  File \"/srv/conda/envs/notebook/lib/python3.12/site-packages/aiida/engine/processes/calcjobs/manager.py\", line 109, in _get_jobs_from_scheduler\n    scheduler_response = scheduler.get_jobs(**kwargs)\n                         ^^^^^^^^^^^^^^^^^^^^^^^^^^^^\n  File \"/srv/conda/envs/notebook/lib/python3.12/site-packages/aiida/schedulers/plugins/direct.py\", line 269, in get_jobs\n    job_stats = super().get_jobs(jobs=jobs, user=user, as_dict=as_dict)\n                ^^^^^^^^^^^^^^^^^^^^^^^^^^^^^^^^^^^^^^^^^^^^^^^^^^^^^^^\n  File \"/srv/conda/envs/notebook/lib/python3.12/site-packages/aiida/schedulers/scheduler.py\", line 361, in get_jobs\n    joblist = self._parse_joblist_output(retval, stdout, stderr)\n              ^^^^^^^^^^^^^^^^^^^^^^^^^^^^^^^^^^^^^^^^^^^^^^^^^^\n  File \"/srv/conda/envs/notebook/lib/python3.12/site-packages/aiida/schedulers/plugins/direct.py\", line 253, in _parse_joblist_output\n    this_job.wallclock_time_seconds = self._convert_time(job[3])\n                                                         ~~~^^^\nIndexError: list index out of range\n03/22/2025 08:35:37 AM <193> aiida.scheduler.direct: [WARNING] Unrecognized job_state 'p' for job id Activating\n03/22/2025 08:35:37 AM <193> aiida.engine.transports: [ERROR] Exception whilst using transport:\nTraceback (most recent call last):\n  File \"/srv/conda/envs/notebook/lib/python3.12/site-packages/aiida/engine/transports.py\", line 106, in request_transport\n    yield transport_request.future\n  File \"/srv/conda/envs/notebook/lib/python3.12/site-packages/aiida/engine/processes/calcjobs/manager.py\", line 109, in _get_jobs_from_scheduler\n    scheduler_response = scheduler.get_jobs(**kwargs)\n                         ^^^^^^^^^^^^^^^^^^^^^^^^^^^^\n  File \"/srv/conda/envs/notebook/lib/python3.12/site-packages/aiida/schedulers/plugins/direct.py\", line 269, in get_jobs\n    job_stats = super().get_jobs(jobs=jobs, user=user, as_dict=as_dict)\n                ^^^^^^^^^^^^^^^^^^^^^^^^^^^^^^^^^^^^^^^^^^^^^^^^^^^^^^^\n  File \"/srv/conda/envs/notebook/lib/python3.12/site-packages/aiida/schedulers/scheduler.py\", line 361, in get_jobs\n    joblist = self._parse_joblist_output(retval, stdout, stderr)\n              ^^^^^^^^^^^^^^^^^^^^^^^^^^^^^^^^^^^^^^^^^^^^^^^^^^\n  File \"/srv/conda/envs/notebook/lib/python3.12/site-packages/aiida/schedulers/plugins/direct.py\", line 253, in _parse_joblist_output\n    this_job.wallclock_time_seconds = self._convert_time(job[3])\n                                                         ~~~^^^\nIndexError: list index out of range\n\nTask exception was never retrieved\nfuture: <Task finished name='Task-66' coro=<JobsList._ensure_updating.<locals>.updating() done, defined at /srv/conda/envs/notebook/lib/python3.12/site-packages/aiida/engine/processes/calcjobs/manager.py:179> exception=IndexError('list index out of range')>\nTraceback (most recent call last):\n  File \"/srv/conda/envs/notebook/lib/python3.12/asyncio/tasks.py\", line 314, in __step_run_and_handle_result\n    result = coro.send(None)\n             ^^^^^^^^^^^^^^^\n  File \"/srv/conda/envs/notebook/lib/python3.12/site-packages/aiida/engine/processes/calcjobs/manager.py\", line 181, in updating\n    await self._update_job_info()\n  File \"/srv/conda/envs/notebook/lib/python3.12/site-packages/aiida/engine/processes/calcjobs/manager.py\", line 132, in _update_job_info\n    self._jobs_cache = await self._get_jobs_from_scheduler()\n                       ^^^^^^^^^^^^^^^^^^^^^^^^^^^^^^^^^^^^^\n  File \"/srv/conda/envs/notebook/lib/python3.12/site-packages/aiida/engine/processes/calcjobs/manager.py\", line 109, in _get_jobs_from_scheduler\n    scheduler_response = scheduler.get_jobs(**kwargs)\n                         ^^^^^^^^^^^^^^^^^^^^^^^^^^^^\n  File \"/srv/conda/envs/notebook/lib/python3.12/site-packages/aiida/schedulers/plugins/direct.py\", line 269, in get_jobs\n    job_stats = super().get_jobs(jobs=jobs, user=user, as_dict=as_dict)\n                ^^^^^^^^^^^^^^^^^^^^^^^^^^^^^^^^^^^^^^^^^^^^^^^^^^^^^^^\n  File \"/srv/conda/envs/notebook/lib/python3.12/site-packages/aiida/schedulers/scheduler.py\", line 361, in get_jobs\n    joblist = self._parse_joblist_output(retval, stdout, stderr)\n              ^^^^^^^^^^^^^^^^^^^^^^^^^^^^^^^^^^^^^^^^^^^^^^^^^^\n  File \"/srv/conda/envs/notebook/lib/python3.12/site-packages/aiida/schedulers/plugins/direct.py\", line 253, in _parse_joblist_output\n    this_job.wallclock_time_seconds = self._convert_time(job[3])\n                                                         ~~~^^^\nIndexError: list index out of range\n03/22/2025 08:35:37 AM <193> aiida.orm.nodes.process.calculation.calcjob.CalcJobNode: [ERROR] iteration 3 of do_update excepted, retrying after 80 seconds\nTraceback (most recent call last):\n  File \"/srv/conda/envs/notebook/lib/python3.12/site-packages/aiida/engine/utils.py\", line 205, in exponential_backoff_retry\n    result = await coro()\n             ^^^^^^^^^^^^\n  File \"/srv/conda/envs/notebook/lib/python3.12/site-packages/aiida/engine/processes/calcjobs/tasks.py\", line 195, in do_update\n    job_info = await cancellable.with_interrupt(update_request)\n               ^^^^^^^^^^^^^^^^^^^^^^^^^^^^^^^^^^^^^^^^^^^^^^^^\n  File \"/srv/conda/envs/notebook/lib/python3.12/site-packages/aiida/engine/utils.py\", line 115, in with_interrupt\n    result = await next(wait_iter)\n             ^^^^^^^^^^^^^^^^^^^^^\n  File \"/srv/conda/envs/notebook/lib/python3.12/asyncio/tasks.py\", line 631, in _wait_for_one\n    return f.result()  # May raise f.exception().\n           ^^^^^^^^^^\n  File \"/srv/conda/envs/notebook/lib/python3.12/asyncio/futures.py\", line 202, in result\n    raise self._exception.with_traceback(self._exception_tb)\n  File \"/srv/conda/envs/notebook/lib/python3.12/site-packages/aiida/engine/processes/calcjobs/manager.py\", line 132, in _update_job_info\n    self._jobs_cache = await self._get_jobs_from_scheduler()\n                       ^^^^^^^^^^^^^^^^^^^^^^^^^^^^^^^^^^^^^\n  File \"/srv/conda/envs/notebook/lib/python3.12/site-packages/aiida/engine/processes/calcjobs/manager.py\", line 109, in _get_jobs_from_scheduler\n    scheduler_response = scheduler.get_jobs(**kwargs)\n                         ^^^^^^^^^^^^^^^^^^^^^^^^^^^^\n  File \"/srv/conda/envs/notebook/lib/python3.12/site-packages/aiida/schedulers/plugins/direct.py\", line 269, in get_jobs\n    job_stats = super().get_jobs(jobs=jobs, user=user, as_dict=as_dict)\n                ^^^^^^^^^^^^^^^^^^^^^^^^^^^^^^^^^^^^^^^^^^^^^^^^^^^^^^^\n  File \"/srv/conda/envs/notebook/lib/python3.12/site-packages/aiida/schedulers/scheduler.py\", line 361, in get_jobs\n    joblist = self._parse_joblist_output(retval, stdout, stderr)\n              ^^^^^^^^^^^^^^^^^^^^^^^^^^^^^^^^^^^^^^^^^^^^^^^^^^\n  File \"/srv/conda/envs/notebook/lib/python3.12/site-packages/aiida/schedulers/plugins/direct.py\", line 253, in _parse_joblist_output\n    this_job.wallclock_time_seconds = self._convert_time(job[3])\n                                                         ~~~^^^\nIndexError: list index out of range\n03/22/2025 08:35:37 AM <193> aiida.scheduler.direct: [WARNING] Unrecognized job_state 'p' for job id Activating\n03/22/2025 08:35:37 AM <193> aiida.engine.transports: [ERROR] Exception whilst using transport:\nTraceback (most recent call last):\n  File \"/srv/conda/envs/notebook/lib/python3.12/site-packages/aiida/engine/transports.py\", line 106, in request_transport\n    yield transport_request.future\n  File \"/srv/conda/envs/notebook/lib/python3.12/site-packages/aiida/engine/processes/calcjobs/manager.py\", line 109, in _get_jobs_from_scheduler\n    scheduler_response = scheduler.get_jobs(**kwargs)\n                         ^^^^^^^^^^^^^^^^^^^^^^^^^^^^\n  File \"/srv/conda/envs/notebook/lib/python3.12/site-packages/aiida/schedulers/plugins/direct.py\", line 269, in get_jobs\n    job_stats = super().get_jobs(jobs=jobs, user=user, as_dict=as_dict)\n                ^^^^^^^^^^^^^^^^^^^^^^^^^^^^^^^^^^^^^^^^^^^^^^^^^^^^^^^\n  File \"/srv/conda/envs/notebook/lib/python3.12/site-packages/aiida/schedulers/scheduler.py\", line 361, in get_jobs\n    joblist = self._parse_joblist_output(retval, stdout, stderr)\n              ^^^^^^^^^^^^^^^^^^^^^^^^^^^^^^^^^^^^^^^^^^^^^^^^^^\n  File \"/srv/conda/envs/notebook/lib/python3.12/site-packages/aiida/schedulers/plugins/direct.py\", line 253, in _parse_joblist_output\n    this_job.wallclock_time_seconds = self._convert_time(job[3])\n                                                         ~~~^^^\nIndexError: list index out of range\n\nTask exception was never retrieved\nfuture: <Task finished name='Task-67' coro=<JobsList._ensure_updating.<locals>.updating() done, defined at /srv/conda/envs/notebook/lib/python3.12/site-packages/aiida/engine/processes/calcjobs/manager.py:179> exception=IndexError('list index out of range')>\nTraceback (most recent call last):\n  File \"/srv/conda/envs/notebook/lib/python3.12/asyncio/tasks.py\", line 314, in __step_run_and_handle_result\n    result = coro.send(None)\n             ^^^^^^^^^^^^^^^\n  File \"/srv/conda/envs/notebook/lib/python3.12/site-packages/aiida/engine/processes/calcjobs/manager.py\", line 181, in updating\n    await self._update_job_info()\n  File \"/srv/conda/envs/notebook/lib/python3.12/site-packages/aiida/engine/processes/calcjobs/manager.py\", line 132, in _update_job_info\n    self._jobs_cache = await self._get_jobs_from_scheduler()\n                       ^^^^^^^^^^^^^^^^^^^^^^^^^^^^^^^^^^^^^\n  File \"/srv/conda/envs/notebook/lib/python3.12/site-packages/aiida/engine/processes/calcjobs/manager.py\", line 109, in _get_jobs_from_scheduler\n    scheduler_response = scheduler.get_jobs(**kwargs)\n                         ^^^^^^^^^^^^^^^^^^^^^^^^^^^^\n  File \"/srv/conda/envs/notebook/lib/python3.12/site-packages/aiida/schedulers/plugins/direct.py\", line 269, in get_jobs\n    job_stats = super().get_jobs(jobs=jobs, user=user, as_dict=as_dict)\n                ^^^^^^^^^^^^^^^^^^^^^^^^^^^^^^^^^^^^^^^^^^^^^^^^^^^^^^^\n  File \"/srv/conda/envs/notebook/lib/python3.12/site-packages/aiida/schedulers/scheduler.py\", line 361, in get_jobs\n    joblist = self._parse_joblist_output(retval, stdout, stderr)\n              ^^^^^^^^^^^^^^^^^^^^^^^^^^^^^^^^^^^^^^^^^^^^^^^^^^\n  File \"/srv/conda/envs/notebook/lib/python3.12/site-packages/aiida/schedulers/plugins/direct.py\", line 253, in _parse_joblist_output\n    this_job.wallclock_time_seconds = self._convert_time(job[3])\n                                                         ~~~^^^\nIndexError: list index out of range\n03/22/2025 08:35:37 AM <193> aiida.orm.nodes.process.calculation.calcjob.CalcJobNode: [ERROR] iteration 3 of do_update excepted, retrying after 80 seconds\nTraceback (most recent call last):\n  File \"/srv/conda/envs/notebook/lib/python3.12/site-packages/aiida/engine/utils.py\", line 205, in exponential_backoff_retry\n    result = await coro()\n             ^^^^^^^^^^^^\n  File \"/srv/conda/envs/notebook/lib/python3.12/site-packages/aiida/engine/processes/calcjobs/tasks.py\", line 195, in do_update\n    job_info = await cancellable.with_interrupt(update_request)\n               ^^^^^^^^^^^^^^^^^^^^^^^^^^^^^^^^^^^^^^^^^^^^^^^^\n  File \"/srv/conda/envs/notebook/lib/python3.12/site-packages/aiida/engine/utils.py\", line 115, in with_interrupt\n    result = await next(wait_iter)\n             ^^^^^^^^^^^^^^^^^^^^^\n  File \"/srv/conda/envs/notebook/lib/python3.12/asyncio/tasks.py\", line 631, in _wait_for_one\n    return f.result()  # May raise f.exception().\n           ^^^^^^^^^^\n  File \"/srv/conda/envs/notebook/lib/python3.12/asyncio/futures.py\", line 202, in result\n    raise self._exception.with_traceback(self._exception_tb)\n  File \"/srv/conda/envs/notebook/lib/python3.12/site-packages/aiida/engine/processes/calcjobs/manager.py\", line 132, in _update_job_info\n    self._jobs_cache = await self._get_jobs_from_scheduler()\n                       ^^^^^^^^^^^^^^^^^^^^^^^^^^^^^^^^^^^^^\n  File \"/srv/conda/envs/notebook/lib/python3.12/site-packages/aiida/engine/processes/calcjobs/manager.py\", line 109, in _get_jobs_from_scheduler\n    scheduler_response = scheduler.get_jobs(**kwargs)\n                         ^^^^^^^^^^^^^^^^^^^^^^^^^^^^\n  File \"/srv/conda/envs/notebook/lib/python3.12/site-packages/aiida/schedulers/plugins/direct.py\", line 269, in get_jobs\n    job_stats = super().get_jobs(jobs=jobs, user=user, as_dict=as_dict)\n                ^^^^^^^^^^^^^^^^^^^^^^^^^^^^^^^^^^^^^^^^^^^^^^^^^^^^^^^\n  File \"/srv/conda/envs/notebook/lib/python3.12/site-packages/aiida/schedulers/scheduler.py\", line 361, in get_jobs\n    joblist = self._parse_joblist_output(retval, stdout, stderr)\n              ^^^^^^^^^^^^^^^^^^^^^^^^^^^^^^^^^^^^^^^^^^^^^^^^^^\n  File \"/srv/conda/envs/notebook/lib/python3.12/site-packages/aiida/schedulers/plugins/direct.py\", line 253, in _parse_joblist_output\n    this_job.wallclock_time_seconds = self._convert_time(job[3])\n                                                         ~~~^^^\nIndexError: list index out of range\n03/22/2025 08:35:37 AM <193> aiida.orm.nodes.process.calculation.calcjob.CalcJobNode: [ERROR] iteration 3 of do_update excepted, retrying after 80 seconds\nTraceback (most recent call last):\n  File \"/srv/conda/envs/notebook/lib/python3.12/site-packages/aiida/engine/utils.py\", line 205, in exponential_backoff_retry\n    result = await coro()\n             ^^^^^^^^^^^^\n  File \"/srv/conda/envs/notebook/lib/python3.12/site-packages/aiida/engine/processes/calcjobs/tasks.py\", line 195, in do_update\n    job_info = await cancellable.with_interrupt(update_request)\n               ^^^^^^^^^^^^^^^^^^^^^^^^^^^^^^^^^^^^^^^^^^^^^^^^\n  File \"/srv/conda/envs/notebook/lib/python3.12/site-packages/aiida/engine/utils.py\", line 115, in with_interrupt\n    result = await next(wait_iter)\n             ^^^^^^^^^^^^^^^^^^^^^\n  File \"/srv/conda/envs/notebook/lib/python3.12/asyncio/tasks.py\", line 631, in _wait_for_one\n    return f.result()  # May raise f.exception().\n           ^^^^^^^^^^\n  File \"/srv/conda/envs/notebook/lib/python3.12/asyncio/futures.py\", line 202, in result\n    raise self._exception.with_traceback(self._exception_tb)\n  File \"/srv/conda/envs/notebook/lib/python3.12/site-packages/aiida/engine/processes/calcjobs/manager.py\", line 132, in _update_job_info\n    self._jobs_cache = await self._get_jobs_from_scheduler()\n                       ^^^^^^^^^^^^^^^^^^^^^^^^^^^^^^^^^^^^^\n  File \"/srv/conda/envs/notebook/lib/python3.12/site-packages/aiida/engine/processes/calcjobs/manager.py\", line 109, in _get_jobs_from_scheduler\n    scheduler_response = scheduler.get_jobs(**kwargs)\n                         ^^^^^^^^^^^^^^^^^^^^^^^^^^^^\n  File \"/srv/conda/envs/notebook/lib/python3.12/site-packages/aiida/schedulers/plugins/direct.py\", line 269, in get_jobs\n    job_stats = super().get_jobs(jobs=jobs, user=user, as_dict=as_dict)\n                ^^^^^^^^^^^^^^^^^^^^^^^^^^^^^^^^^^^^^^^^^^^^^^^^^^^^^^^\n  File \"/srv/conda/envs/notebook/lib/python3.12/site-packages/aiida/schedulers/scheduler.py\", line 361, in get_jobs\n    joblist = self._parse_joblist_output(retval, stdout, stderr)\n              ^^^^^^^^^^^^^^^^^^^^^^^^^^^^^^^^^^^^^^^^^^^^^^^^^^\n  File \"/srv/conda/envs/notebook/lib/python3.12/site-packages/aiida/schedulers/plugins/direct.py\", line 253, in _parse_joblist_output\n    this_job.wallclock_time_seconds = self._convert_time(job[3])\n                                                         ~~~^^^\nIndexError: list index out of range\n03/22/2025 08:35:37 AM <193> aiida.orm.nodes.process.calculation.calcjob.CalcJobNode: [ERROR] iteration 3 of do_update excepted, retrying after 80 seconds\nTraceback (most recent call last):\n  File \"/srv/conda/envs/notebook/lib/python3.12/site-packages/aiida/engine/utils.py\", line 205, in exponential_backoff_retry\n    result = await coro()\n             ^^^^^^^^^^^^\n  File \"/srv/conda/envs/notebook/lib/python3.12/site-packages/aiida/engine/processes/calcjobs/tasks.py\", line 195, in do_update\n    job_info = await cancellable.with_interrupt(update_request)\n               ^^^^^^^^^^^^^^^^^^^^^^^^^^^^^^^^^^^^^^^^^^^^^^^^\n  File \"/srv/conda/envs/notebook/lib/python3.12/site-packages/aiida/engine/utils.py\", line 115, in with_interrupt\n    result = await next(wait_iter)\n             ^^^^^^^^^^^^^^^^^^^^^\n  File \"/srv/conda/envs/notebook/lib/python3.12/asyncio/tasks.py\", line 631, in _wait_for_one\n    return f.result()  # May raise f.exception().\n           ^^^^^^^^^^\n  File \"/srv/conda/envs/notebook/lib/python3.12/asyncio/futures.py\", line 202, in result\n    raise self._exception.with_traceback(self._exception_tb)\n  File \"/srv/conda/envs/notebook/lib/python3.12/site-packages/aiida/engine/processes/calcjobs/manager.py\", line 132, in _update_job_info\n    self._jobs_cache = await self._get_jobs_from_scheduler()\n                       ^^^^^^^^^^^^^^^^^^^^^^^^^^^^^^^^^^^^^\n  File \"/srv/conda/envs/notebook/lib/python3.12/site-packages/aiida/engine/processes/calcjobs/manager.py\", line 109, in _get_jobs_from_scheduler\n    scheduler_response = scheduler.get_jobs(**kwargs)\n                         ^^^^^^^^^^^^^^^^^^^^^^^^^^^^\n  File \"/srv/conda/envs/notebook/lib/python3.12/site-packages/aiida/schedulers/plugins/direct.py\", line 269, in get_jobs\n    job_stats = super().get_jobs(jobs=jobs, user=user, as_dict=as_dict)\n                ^^^^^^^^^^^^^^^^^^^^^^^^^^^^^^^^^^^^^^^^^^^^^^^^^^^^^^^\n  File \"/srv/conda/envs/notebook/lib/python3.12/site-packages/aiida/schedulers/scheduler.py\", line 361, in get_jobs\n    joblist = self._parse_joblist_output(retval, stdout, stderr)\n              ^^^^^^^^^^^^^^^^^^^^^^^^^^^^^^^^^^^^^^^^^^^^^^^^^^\n  File \"/srv/conda/envs/notebook/lib/python3.12/site-packages/aiida/schedulers/plugins/direct.py\", line 253, in _parse_joblist_output\n    this_job.wallclock_time_seconds = self._convert_time(job[3])\n                                                         ~~~^^^\nIndexError: list index out of range\n03/22/2025 08:35:37 AM <193> aiida.orm.nodes.process.calculation.calcjob.CalcJobNode: [ERROR] iteration 3 of do_update excepted, retrying after 80 seconds\nTraceback (most recent call last):\n  File \"/srv/conda/envs/notebook/lib/python3.12/site-packages/aiida/engine/utils.py\", line 205, in exponential_backoff_retry\n    result = await coro()\n             ^^^^^^^^^^^^\n  File \"/srv/conda/envs/notebook/lib/python3.12/site-packages/aiida/engine/processes/calcjobs/tasks.py\", line 195, in do_update\n    job_info = await cancellable.with_interrupt(update_request)\n               ^^^^^^^^^^^^^^^^^^^^^^^^^^^^^^^^^^^^^^^^^^^^^^^^\n  File \"/srv/conda/envs/notebook/lib/python3.12/site-packages/aiida/engine/utils.py\", line 115, in with_interrupt\n    result = await next(wait_iter)\n             ^^^^^^^^^^^^^^^^^^^^^\n  File \"/srv/conda/envs/notebook/lib/python3.12/asyncio/tasks.py\", line 631, in _wait_for_one\n    return f.result()  # May raise f.exception().\n           ^^^^^^^^^^\n  File \"/srv/conda/envs/notebook/lib/python3.12/asyncio/futures.py\", line 202, in result\n    raise self._exception.with_traceback(self._exception_tb)\n  File \"/srv/conda/envs/notebook/lib/python3.12/site-packages/aiida/engine/processes/calcjobs/manager.py\", line 132, in _update_job_info\n    self._jobs_cache = await self._get_jobs_from_scheduler()\n                       ^^^^^^^^^^^^^^^^^^^^^^^^^^^^^^^^^^^^^\n  File \"/srv/conda/envs/notebook/lib/python3.12/site-packages/aiida/engine/processes/calcjobs/manager.py\", line 109, in _get_jobs_from_scheduler\n    scheduler_response = scheduler.get_jobs(**kwargs)\n                         ^^^^^^^^^^^^^^^^^^^^^^^^^^^^\n  File \"/srv/conda/envs/notebook/lib/python3.12/site-packages/aiida/schedulers/plugins/direct.py\", line 269, in get_jobs\n    job_stats = super().get_jobs(jobs=jobs, user=user, as_dict=as_dict)\n                ^^^^^^^^^^^^^^^^^^^^^^^^^^^^^^^^^^^^^^^^^^^^^^^^^^^^^^^\n  File \"/srv/conda/envs/notebook/lib/python3.12/site-packages/aiida/schedulers/scheduler.py\", line 361, in get_jobs\n    joblist = self._parse_joblist_output(retval, stdout, stderr)\n              ^^^^^^^^^^^^^^^^^^^^^^^^^^^^^^^^^^^^^^^^^^^^^^^^^^\n  File \"/srv/conda/envs/notebook/lib/python3.12/site-packages/aiida/schedulers/plugins/direct.py\", line 253, in _parse_joblist_output\n    this_job.wallclock_time_seconds = self._convert_time(job[3])\n                                                         ~~~^^^\nIndexError: list index out of range\n03/22/2025 08:35:37 AM <193> aiida.orm.nodes.process.calculation.calcjob.CalcJobNode: [ERROR] iteration 3 of do_update excepted, retrying after 80 seconds\nTraceback (most recent call last):\n  File \"/srv/conda/envs/notebook/lib/python3.12/site-packages/aiida/engine/utils.py\", line 205, in exponential_backoff_retry\n    result = await coro()\n             ^^^^^^^^^^^^\n  File \"/srv/conda/envs/notebook/lib/python3.12/site-packages/aiida/engine/processes/calcjobs/tasks.py\", line 195, in do_update\n    job_info = await cancellable.with_interrupt(update_request)\n               ^^^^^^^^^^^^^^^^^^^^^^^^^^^^^^^^^^^^^^^^^^^^^^^^\n  File \"/srv/conda/envs/notebook/lib/python3.12/site-packages/aiida/engine/utils.py\", line 115, in with_interrupt\n    result = await next(wait_iter)\n             ^^^^^^^^^^^^^^^^^^^^^\n  File \"/srv/conda/envs/notebook/lib/python3.12/asyncio/tasks.py\", line 631, in _wait_for_one\n    return f.result()  # May raise f.exception().\n           ^^^^^^^^^^\n  File \"/srv/conda/envs/notebook/lib/python3.12/asyncio/futures.py\", line 202, in result\n    raise self._exception.with_traceback(self._exception_tb)\n  File \"/srv/conda/envs/notebook/lib/python3.12/site-packages/aiida/engine/processes/calcjobs/manager.py\", line 132, in _update_job_info\n    self._jobs_cache = await self._get_jobs_from_scheduler()\n                       ^^^^^^^^^^^^^^^^^^^^^^^^^^^^^^^^^^^^^\n  File \"/srv/conda/envs/notebook/lib/python3.12/site-packages/aiida/engine/processes/calcjobs/manager.py\", line 109, in _get_jobs_from_scheduler\n    scheduler_response = scheduler.get_jobs(**kwargs)\n                         ^^^^^^^^^^^^^^^^^^^^^^^^^^^^\n  File \"/srv/conda/envs/notebook/lib/python3.12/site-packages/aiida/schedulers/plugins/direct.py\", line 269, in get_jobs\n    job_stats = super().get_jobs(jobs=jobs, user=user, as_dict=as_dict)\n                ^^^^^^^^^^^^^^^^^^^^^^^^^^^^^^^^^^^^^^^^^^^^^^^^^^^^^^^\n  File \"/srv/conda/envs/notebook/lib/python3.12/site-packages/aiida/schedulers/scheduler.py\", line 361, in get_jobs\n    joblist = self._parse_joblist_output(retval, stdout, stderr)\n              ^^^^^^^^^^^^^^^^^^^^^^^^^^^^^^^^^^^^^^^^^^^^^^^^^^\n  File \"/srv/conda/envs/notebook/lib/python3.12/site-packages/aiida/schedulers/plugins/direct.py\", line 253, in _parse_joblist_output\n    this_job.wallclock_time_seconds = self._convert_time(job[3])\n                                                         ~~~^^^\nIndexError: list index out of range\n03/22/2025 08:35:37 AM <193> aiida.orm.nodes.process.calculation.calcjob.CalcJobNode: [ERROR] iteration 3 of do_update excepted, retrying after 80 seconds\nTraceback (most recent call last):\n  File \"/srv/conda/envs/notebook/lib/python3.12/site-packages/aiida/engine/utils.py\", line 205, in exponential_backoff_retry\n    result = await coro()\n             ^^^^^^^^^^^^\n  File \"/srv/conda/envs/notebook/lib/python3.12/site-packages/aiida/engine/processes/calcjobs/tasks.py\", line 195, in do_update\n    job_info = await cancellable.with_interrupt(update_request)\n               ^^^^^^^^^^^^^^^^^^^^^^^^^^^^^^^^^^^^^^^^^^^^^^^^\n  File \"/srv/conda/envs/notebook/lib/python3.12/site-packages/aiida/engine/utils.py\", line 115, in with_interrupt\n    result = await next(wait_iter)\n             ^^^^^^^^^^^^^^^^^^^^^\n  File \"/srv/conda/envs/notebook/lib/python3.12/asyncio/tasks.py\", line 631, in _wait_for_one\n    return f.result()  # May raise f.exception().\n           ^^^^^^^^^^\n  File \"/srv/conda/envs/notebook/lib/python3.12/asyncio/futures.py\", line 202, in result\n    raise self._exception.with_traceback(self._exception_tb)\n  File \"/srv/conda/envs/notebook/lib/python3.12/site-packages/aiida/engine/processes/calcjobs/manager.py\", line 132, in _update_job_info\n    self._jobs_cache = await self._get_jobs_from_scheduler()\n                       ^^^^^^^^^^^^^^^^^^^^^^^^^^^^^^^^^^^^^\n  File \"/srv/conda/envs/notebook/lib/python3.12/site-packages/aiida/engine/processes/calcjobs/manager.py\", line 109, in _get_jobs_from_scheduler\n    scheduler_response = scheduler.get_jobs(**kwargs)\n                         ^^^^^^^^^^^^^^^^^^^^^^^^^^^^\n  File \"/srv/conda/envs/notebook/lib/python3.12/site-packages/aiida/schedulers/plugins/direct.py\", line 269, in get_jobs\n    job_stats = super().get_jobs(jobs=jobs, user=user, as_dict=as_dict)\n                ^^^^^^^^^^^^^^^^^^^^^^^^^^^^^^^^^^^^^^^^^^^^^^^^^^^^^^^\n  File \"/srv/conda/envs/notebook/lib/python3.12/site-packages/aiida/schedulers/scheduler.py\", line 361, in get_jobs\n    joblist = self._parse_joblist_output(retval, stdout, stderr)\n              ^^^^^^^^^^^^^^^^^^^^^^^^^^^^^^^^^^^^^^^^^^^^^^^^^^\n  File \"/srv/conda/envs/notebook/lib/python3.12/site-packages/aiida/schedulers/plugins/direct.py\", line 253, in _parse_joblist_output\n    this_job.wallclock_time_seconds = self._convert_time(job[3])\n                                                         ~~~^^^\nIndexError: list index out of range\n03/22/2025 08:35:37 AM <193> aiida.orm.nodes.process.calculation.calcjob.CalcJobNode: [ERROR] iteration 3 of do_update excepted, retrying after 80 seconds\nTraceback (most recent call last):\n  File \"/srv/conda/envs/notebook/lib/python3.12/site-packages/aiida/engine/utils.py\", line 205, in exponential_backoff_retry\n    result = await coro()\n             ^^^^^^^^^^^^\n  File \"/srv/conda/envs/notebook/lib/python3.12/site-packages/aiida/engine/processes/calcjobs/tasks.py\", line 195, in do_update\n    job_info = await cancellable.with_interrupt(update_request)\n               ^^^^^^^^^^^^^^^^^^^^^^^^^^^^^^^^^^^^^^^^^^^^^^^^\n  File \"/srv/conda/envs/notebook/lib/python3.12/site-packages/aiida/engine/utils.py\", line 115, in with_interrupt\n    result = await next(wait_iter)\n             ^^^^^^^^^^^^^^^^^^^^^\n  File \"/srv/conda/envs/notebook/lib/python3.12/asyncio/tasks.py\", line 631, in _wait_for_one\n    return f.result()  # May raise f.exception().\n           ^^^^^^^^^^\n  File \"/srv/conda/envs/notebook/lib/python3.12/asyncio/futures.py\", line 202, in result\n    raise self._exception.with_traceback(self._exception_tb)\n  File \"/srv/conda/envs/notebook/lib/python3.12/site-packages/aiida/engine/processes/calcjobs/manager.py\", line 132, in _update_job_info\n    self._jobs_cache = await self._get_jobs_from_scheduler()\n                       ^^^^^^^^^^^^^^^^^^^^^^^^^^^^^^^^^^^^^\n  File \"/srv/conda/envs/notebook/lib/python3.12/site-packages/aiida/engine/processes/calcjobs/manager.py\", line 109, in _get_jobs_from_scheduler\n    scheduler_response = scheduler.get_jobs(**kwargs)\n                         ^^^^^^^^^^^^^^^^^^^^^^^^^^^^\n  File \"/srv/conda/envs/notebook/lib/python3.12/site-packages/aiida/schedulers/plugins/direct.py\", line 269, in get_jobs\n    job_stats = super().get_jobs(jobs=jobs, user=user, as_dict=as_dict)\n                ^^^^^^^^^^^^^^^^^^^^^^^^^^^^^^^^^^^^^^^^^^^^^^^^^^^^^^^\n  File \"/srv/conda/envs/notebook/lib/python3.12/site-packages/aiida/schedulers/scheduler.py\", line 361, in get_jobs\n    joblist = self._parse_joblist_output(retval, stdout, stderr)\n              ^^^^^^^^^^^^^^^^^^^^^^^^^^^^^^^^^^^^^^^^^^^^^^^^^^\n  File \"/srv/conda/envs/notebook/lib/python3.12/site-packages/aiida/schedulers/plugins/direct.py\", line 253, in _parse_joblist_output\n    this_job.wallclock_time_seconds = self._convert_time(job[3])\n                                                         ~~~^^^\nIndexError: list index out of range\n03/22/2025 08:35:37 AM <193> aiida.orm.nodes.process.calculation.calcjob.CalcJobNode: [ERROR] iteration 3 of do_update excepted, retrying after 80 seconds\nTraceback (most recent call last):\n  File \"/srv/conda/envs/notebook/lib/python3.12/site-packages/aiida/engine/utils.py\", line 205, in exponential_backoff_retry\n    result = await coro()\n             ^^^^^^^^^^^^\n  File \"/srv/conda/envs/notebook/lib/python3.12/site-packages/aiida/engine/processes/calcjobs/tasks.py\", line 195, in do_update\n    job_info = await cancellable.with_interrupt(update_request)\n               ^^^^^^^^^^^^^^^^^^^^^^^^^^^^^^^^^^^^^^^^^^^^^^^^\n  File \"/srv/conda/envs/notebook/lib/python3.12/site-packages/aiida/engine/utils.py\", line 115, in with_interrupt\n    result = await next(wait_iter)\n             ^^^^^^^^^^^^^^^^^^^^^\n  File \"/srv/conda/envs/notebook/lib/python3.12/asyncio/tasks.py\", line 631, in _wait_for_one\n    return f.result()  # May raise f.exception().\n           ^^^^^^^^^^\n  File \"/srv/conda/envs/notebook/lib/python3.12/asyncio/futures.py\", line 202, in result\n    raise self._exception.with_traceback(self._exception_tb)\n  File \"/srv/conda/envs/notebook/lib/python3.12/site-packages/aiida/engine/processes/calcjobs/manager.py\", line 132, in _update_job_info\n    self._jobs_cache = await self._get_jobs_from_scheduler()\n                       ^^^^^^^^^^^^^^^^^^^^^^^^^^^^^^^^^^^^^\n  File \"/srv/conda/envs/notebook/lib/python3.12/site-packages/aiida/engine/processes/calcjobs/manager.py\", line 109, in _get_jobs_from_scheduler\n    scheduler_response = scheduler.get_jobs(**kwargs)\n                         ^^^^^^^^^^^^^^^^^^^^^^^^^^^^\n  File \"/srv/conda/envs/notebook/lib/python3.12/site-packages/aiida/schedulers/plugins/direct.py\", line 269, in get_jobs\n    job_stats = super().get_jobs(jobs=jobs, user=user, as_dict=as_dict)\n                ^^^^^^^^^^^^^^^^^^^^^^^^^^^^^^^^^^^^^^^^^^^^^^^^^^^^^^^\n  File \"/srv/conda/envs/notebook/lib/python3.12/site-packages/aiida/schedulers/scheduler.py\", line 361, in get_jobs\n    joblist = self._parse_joblist_output(retval, stdout, stderr)\n              ^^^^^^^^^^^^^^^^^^^^^^^^^^^^^^^^^^^^^^^^^^^^^^^^^^\n  File \"/srv/conda/envs/notebook/lib/python3.12/site-packages/aiida/schedulers/plugins/direct.py\", line 253, in _parse_joblist_output\n    this_job.wallclock_time_seconds = self._convert_time(job[3])\n                                                         ~~~^^^\nIndexError: list index out of range\n03/22/2025 08:35:37 AM <193> aiida.orm.nodes.process.calculation.calcjob.CalcJobNode: [ERROR] iteration 3 of do_update excepted, retrying after 80 seconds\nTraceback (most recent call last):\n  File \"/srv/conda/envs/notebook/lib/python3.12/site-packages/aiida/engine/utils.py\", line 205, in exponential_backoff_retry\n    result = await coro()\n             ^^^^^^^^^^^^\n  File \"/srv/conda/envs/notebook/lib/python3.12/site-packages/aiida/engine/processes/calcjobs/tasks.py\", line 195, in do_update\n    job_info = await cancellable.with_interrupt(update_request)\n               ^^^^^^^^^^^^^^^^^^^^^^^^^^^^^^^^^^^^^^^^^^^^^^^^\n  File \"/srv/conda/envs/notebook/lib/python3.12/site-packages/aiida/engine/utils.py\", line 115, in with_interrupt\n    result = await next(wait_iter)\n             ^^^^^^^^^^^^^^^^^^^^^\n  File \"/srv/conda/envs/notebook/lib/python3.12/asyncio/tasks.py\", line 631, in _wait_for_one\n    return f.result()  # May raise f.exception().\n           ^^^^^^^^^^\n  File \"/srv/conda/envs/notebook/lib/python3.12/asyncio/futures.py\", line 202, in result\n    raise self._exception.with_traceback(self._exception_tb)\n  File \"/srv/conda/envs/notebook/lib/python3.12/site-packages/aiida/engine/processes/calcjobs/manager.py\", line 132, in _update_job_info\n    self._jobs_cache = await self._get_jobs_from_scheduler()\n                       ^^^^^^^^^^^^^^^^^^^^^^^^^^^^^^^^^^^^^\n  File \"/srv/conda/envs/notebook/lib/python3.12/site-packages/aiida/engine/processes/calcjobs/manager.py\", line 109, in _get_jobs_from_scheduler\n    scheduler_response = scheduler.get_jobs(**kwargs)\n                         ^^^^^^^^^^^^^^^^^^^^^^^^^^^^\n  File \"/srv/conda/envs/notebook/lib/python3.12/site-packages/aiida/schedulers/plugins/direct.py\", line 269, in get_jobs\n    job_stats = super().get_jobs(jobs=jobs, user=user, as_dict=as_dict)\n                ^^^^^^^^^^^^^^^^^^^^^^^^^^^^^^^^^^^^^^^^^^^^^^^^^^^^^^^\n  File \"/srv/conda/envs/notebook/lib/python3.12/site-packages/aiida/schedulers/scheduler.py\", line 361, in get_jobs\n    joblist = self._parse_joblist_output(retval, stdout, stderr)\n              ^^^^^^^^^^^^^^^^^^^^^^^^^^^^^^^^^^^^^^^^^^^^^^^^^^\n  File \"/srv/conda/envs/notebook/lib/python3.12/site-packages/aiida/schedulers/plugins/direct.py\", line 253, in _parse_joblist_output\n    this_job.wallclock_time_seconds = self._convert_time(job[3])\n                                                         ~~~^^^\nIndexError: list index out of range\n03/22/2025 08:35:37 AM <193> aiida.orm.nodes.process.calculation.calcjob.CalcJobNode: [ERROR] iteration 3 of do_update excepted, retrying after 80 seconds\nTraceback (most recent call last):\n  File \"/srv/conda/envs/notebook/lib/python3.12/site-packages/aiida/engine/utils.py\", line 205, in exponential_backoff_retry\n    result = await coro()\n             ^^^^^^^^^^^^\n  File \"/srv/conda/envs/notebook/lib/python3.12/site-packages/aiida/engine/processes/calcjobs/tasks.py\", line 195, in do_update\n    job_info = await cancellable.with_interrupt(update_request)\n               ^^^^^^^^^^^^^^^^^^^^^^^^^^^^^^^^^^^^^^^^^^^^^^^^\n  File \"/srv/conda/envs/notebook/lib/python3.12/site-packages/aiida/engine/utils.py\", line 115, in with_interrupt\n    result = await next(wait_iter)\n             ^^^^^^^^^^^^^^^^^^^^^\n  File \"/srv/conda/envs/notebook/lib/python3.12/asyncio/tasks.py\", line 631, in _wait_for_one\n    return f.result()  # May raise f.exception().\n           ^^^^^^^^^^\n  File \"/srv/conda/envs/notebook/lib/python3.12/asyncio/futures.py\", line 202, in result\n    raise self._exception.with_traceback(self._exception_tb)\n  File \"/srv/conda/envs/notebook/lib/python3.12/site-packages/aiida/engine/processes/calcjobs/manager.py\", line 132, in _update_job_info\n    self._jobs_cache = await self._get_jobs_from_scheduler()\n                       ^^^^^^^^^^^^^^^^^^^^^^^^^^^^^^^^^^^^^\n  File \"/srv/conda/envs/notebook/lib/python3.12/site-packages/aiida/engine/processes/calcjobs/manager.py\", line 109, in _get_jobs_from_scheduler\n    scheduler_response = scheduler.get_jobs(**kwargs)\n                         ^^^^^^^^^^^^^^^^^^^^^^^^^^^^\n  File \"/srv/conda/envs/notebook/lib/python3.12/site-packages/aiida/schedulers/plugins/direct.py\", line 269, in get_jobs\n    job_stats = super().get_jobs(jobs=jobs, user=user, as_dict=as_dict)\n                ^^^^^^^^^^^^^^^^^^^^^^^^^^^^^^^^^^^^^^^^^^^^^^^^^^^^^^^\n  File \"/srv/conda/envs/notebook/lib/python3.12/site-packages/aiida/schedulers/scheduler.py\", line 361, in get_jobs\n    joblist = self._parse_joblist_output(retval, stdout, stderr)\n              ^^^^^^^^^^^^^^^^^^^^^^^^^^^^^^^^^^^^^^^^^^^^^^^^^^\n  File \"/srv/conda/envs/notebook/lib/python3.12/site-packages/aiida/schedulers/plugins/direct.py\", line 253, in _parse_joblist_output\n    this_job.wallclock_time_seconds = self._convert_time(job[3])\n                                                         ~~~^^^\nIndexError: list index out of range\n"
    }
   ],
   "execution_count": null
  },
  {
   "id": "6a8d1a17-3698-4873-8937-616e9e7dc7ca",
   "cell_type": "code",
   "source": "from IPython.display import Image, display\n\nplot_task = [t for t in wg.tasks if t.name.startswith('plot_energy_volume_curve')][0]\nplot_file = f\"{plot_task.node.get_remote_workdir()}/evcurve.png\"\n\ndisplay(Image(filename=str(plot_file)))\n",
   "metadata": {
    "trusted": true
   },
   "outputs": [],
   "execution_count": null
  },
  {
   "id": "c4f5c047-c6da-4b54-9007-415faca7a448",
   "cell_type": "markdown",
   "source": "## Load Workflow with jobflow",
   "metadata": {}
  },
  {
   "id": "b8e3c2ca-2672-4e9d-aada-63344842dbcf",
   "cell_type": "code",
   "source": "from python_workflow_definition.jobflow import load_workflow_json",
   "metadata": {
    "trusted": true
   },
   "outputs": [],
   "execution_count": null
  },
  {
   "metadata": {},
   "cell_type": "code",
   "outputs": [],
   "execution_count": null,
   "source": "from jobflow.managers.local import run_locally",
   "id": "54a24ff6c569094e"
  },
  {
   "id": "48a27146-7372-40ab-8b02-e2a9283d4748",
   "cell_type": "code",
   "source": "flow = load_workflow_json(file_name=workflow_json_filename)",
   "metadata": {
    "trusted": true
   },
   "outputs": [],
   "execution_count": null
  },
  {
   "id": "98fa5694-2cc6-44e9-a6e7-2cc71b4f48ce",
   "cell_type": "code",
   "source": "result = run_locally(flow)\nresult",
   "metadata": {
    "trusted": true
   },
   "outputs": [],
   "execution_count": null
  }
 ]
}
